Workbook

Sheet README
A1: EU4+UK Angelman Syndrome Treatment Centres and KOLs — Mapping & Tiering
A3: Prepared for | B3: Medical Affairs workstream — ION582 / obudanersen (Ionis Pharmaceuticals) (Angelman syndrome)
A4: Geographies | B4: EU4+UK: Germany, France, Italy, Spain, United Kingdom
A5: Date compiled | B5: 14 October 2026
A6: Compiled by | B6: Microsoft Copilot (Opus 5.5) for Ian Pepper
A7: Method | B7: Cross-referenced from public sources (trial registries, sponsor/patient-organisation communications, guidelines, hospital and Orphanet directories). Template: PROMPT_KOL_Centre_Map_v2.
A8: Asset status | B8: ION582 (obudanersen): HALOS Ph1/2 (NCT05127226, 71 enrolled); REVEAL Ph3 (NCT06914609) — Cohort 1 fully enrolled Jul 2026, initial results expected H2 2027. Competitor apazunersen (GTX-102) missed Ph3 Aspire endpoints (2 Sep 2026); rugonersen (Oak Hill Bio) entering Ph3 (BEACON).
A10: Tab guide
A11: Country_Centres | B11: Master flat table — one row per Tier 1–3 centre with P1–P5 flags
A12: KOL_Roster | B12: Named clinicians with signal, scoring and KOL tier for TOV
A13: Tier_Counts | B13: Centre and KOL matrices by country + cross-cuts (formula-driven)
A14: Infrastructure | B14: AS diagnostic/management requirements and ION582 asset overlay
A15: Sources_Caveats | B15: Sources with URLs/DOIs + data-quality caveats
A16: Verification_Flags | B16: Adversarial QA pass — items for human decision
A18: The five signal pillars chosen for Angelman syndrome
A19: P1 — Guideline-author signal | B19: Duis J et al. 2022, 'A multidisciplinary approach and consensus statement to establish standards of care for Angelman syndrome', Mol Genet Genomic Med 10(3):e1843 (PMID 35150089). SUBSTITUTION: no EU4+UK clinician is an author (EU authors are Erasmus MC, NL and Queen Fabiola, BE — outside scope). Country-level analogue used: France PNDS 'Syndrome d'Angelman' (HAS/DéfiScience, Nov 2021, coordinated by Dr Delphine Héron). No equivalent national guideline located for DE, IT, ES or UK.
A20: P2 — Publication / trial-authorship signal | B20: AS disease publications plus ION582 (HALOS NCT05127226; REVEAL NCT06914609) and competitor-ASO trial authorship: rugonersen TANGELO (NCT04428281; Hipp et al., Nat Med 2025, PMID 40646322), apazunersen/GTX-102 (NCT04259281 Ph1/2; Aspire NCT06617429; Aurora NCT07157254). Key national review: Manssen et al., Neuropediatrics 2025 (DOI 10.1055/a-2399-0191).
A21: P3 — Registry / outcome-study signal | B21: SUBSTITUTION: no pan-European AS registry with a public site list. Used the UBE3A-ASO trial-site network (HALOS, REVEAL, Aspire, Aurora, TANGELO) as the trial-ready site proxy, plus the Oxford AS Natural History Study (FAST UK-funded; CI Prof Laurent Servais) and the Global Angelman Syndrome Registry (NCT05293184; patient-reported, no site roles). 'Coordinator' = national lead/chief investigator where publicly named.
A22: P4 — Reference-network signal | B22: ERN ITHACA (rare malformation syndromes, intellectual & neurodevelopmental disorders); ERN EpiCARE secondary. National analogues used where ERN HCP status could not be verified: France CRMR (DéfiScience), Spain XUEC (Catalonia), Italy national rare-disease centre listing (malattierare.gov.it). UK: N/A (post-Brexit) — NHS / national designation used instead.
A23: P5 — Disease-programme signal | B23: Dedicated Angelman syndrome clinic/unit (e.g. ASF-recognised clinic, 'Unidad de Angelman', 'Angelman Zentrum', specialist AS clinic) or a rare-ID/DEE service that explicitly lists AS.
A25: Centre Tier definitions
A26: Tier 1 — Anchor / reference | B26: Hosts a P1 guideline author OR a P3 registry/trial coordinator, AND is a P4 reference-network HCP (or national equivalent), AND carries P2 publication/trial authorship (last ~5 y). Role: first-wave engagement, advisory-board core, ION582 evidence partners.
A27: Tier 2 — National referral | B27: P4 HCP with P5 programme, OR a P3 participating (trial) site; university hospital with specialist care and AS-relevant diagnostics; recurring P2. Role: second-wave outreach, regional hubs.
A28: Tier 3 — Tertiary capable | B28: National/regional reference centre or large university hospital with core infrastructure, typically not research-active in AS. Role: launch distribution, HCP education.
A29: Tier 4 — Community | B29: Not enumerated (not requested). AS is a chronic, managed condition — care concentrates at expert centres; Tier 4 is addressed via national societies and patient organisations.
A31: KOL Tier definitions (scoring)
A32: Domains (1/3/5 pts each) | B32: Guideline authorship (G) · Publications (P) · Clinical trials (T) · Academic appointment (A) · Society roles (S) · Speaker engagement (Sp) · Awards (Aw, 1–2).
A33: 1 point | B33: Local protocols; ≥3 pubs; local/national trial site investigator; specialist; local society member; occasional local speaker.
A34: 3 points | B34: National guideline co-author; ≥5 pubs (7 y); national PI / multi-country investigator; senior physician / assoc. prof; national society board; regular national speaker.
A35: 5 points | B35: International guideline author; ≥5 first/last-author pubs (7 y); lead/site PI in international or pivotal trials; department head / group leader; executive society leadership; international keynote.
A36: Rules | B36: Highest level fully supported by evidence; no inference; default to 1 where evidence is limited; prioritise last 5–7 years.
A37: Tiers | B37: Tier 1 = 24–30 · Tier 2 = 12–23 · Tier 3 = 0–11. Score breakdown shown in KOL_Roster column J.
A39: Critical caveats
A40: Chronic disease | B40: AS is a chronic neurodevelopmental disorder: patients concentrate at expert centres, so the acute-presentation dispersion caveat does not apply.
A41: No EU4+UK P1 apex cohort | B41: The international SoC consensus (Duis 2022) has no EU4+UK authors; France is the only EU4+UK country with a national AS guideline (PNDS 2021). Tier 1 therefore relies on the P3 national-lead substitution.
A42: UK | B42: Post-Brexit: P4 = N/A; tiered on trial/natural-history leadership.
A43: Germany | B43: No German Tier 1 — no national guideline, no publicly named ION582 national lead.
A44: KOL minimum | B44: The 15-KOLs-per-country minimum was NOT met without fabrication (FR 5, DE 10, IT 12, ES 12, UK 5). Shortfall is flagged; no names were invented.
A46: KOL gap-fill methodology
A47: Order applied | B47: (a) P2 senior/corresponding authors on AS or ASO-trial papers → (b) reference-network / CRMR coordinator → (c) national rare-disease / patient-organisation reference-centre lead (OR.S.A., FAST España, AngelmanUK) → (d) hospital directories. Untraceable → 'Not publicly identified — verify locally'.
...

Sheet Country_Centres
A1: Country | B1: Tier | C1: City | D1: Centre / Hospital | E1: Unit / Department | F1: KOL / Lead clinician(s) | G1: Role / Affiliation signal | H1: P1: AS guideline author (Duis 2022 / national PNDS) | I1: P2: AS / ASO-trial publications (5y) | J1: P3: ASO trial / natural-history coord/site | K1: P4: ERN ITHACA HCP (or national analogue) | L1: P5: Dedicated AS programme | M1: Notes
A2: France | B2: 2 | C2: Paris | D2: Hôpital Universitaire Necker-Enfants Malades (AP-HP) | E2: Centre de référence Déficiences intellectuelles et polyhandicaps de causes rares (site constitutif Necker) | F2: Pr Nadia Bahi-Buisson (médecin responsable CRMR site); HALOS site PI: Not publicly identified — verify locally | G2: Only French HALOS (ION582) site; Aurora (GTX-102) site; CRMR site affiliated to ERN ITHACA | H2: No | I2: Yes — ION582 trial (HALOS site); competitor trial (Aurora site) | J2: Site (HALOS; Aurora) | K2: Yes (ERN ITHACA-affiliated CRMR, per AP-HP Necker site) | L2: Partial (Rett/DEE/polyhandicap centre listing AS) | M2: ION582 evidence-partner candidate: first French HALOS patient enrolled by Nov 2023. Upgrade to Tier 1 if HALOS national-lead role or PNDS authorship confirmed.
A3: France | B3: 2 | C3: Paris | D3: Hôpital de la Pitié-Salpêtrière (AP-HP Sorbonne Université) | E3: Centre de Référence Coordonnateur 'Déficiences Intellectuelles de causes rares' (filière DéfiScience) | F3: Dr Delphine Héron (PNDS coordinator) | G3: Coordinated the French national PNDS for Angelman syndrome (HAS, Nov 2021) | H3: Yes — national PNDS (country-level P1) | I3: Qualified — AS-specific 5-y authorship not verified | J3: No | K3: National analogue: CRMR coordonnateur (ERN ITHACA status — verify) | L3: Partial (rare-cause ID reference centre) | M3: National guideline anchor; not an ASO trial site on public lists.
A4: France | B4: 2 | C4: Marseille | D4: Hôpital de la Timone (AP-HM) | E4: Neurologie pédiatrique / neuro-métabolisme — CRMR épilepsies rares; CRMR déficience intellectuelle de cause rare | F4: Pr Mathieu Milh (chef de service); Aurora site PI: Not publicly identified — verify locally | G4: Aurora (GTX-102) site; hosts rare-epilepsy and rare-ID reference centres | H4: No | I4: Yes — competitor trial (Aurora site) | J4: Site (Aurora) | K4: National analogue: CRMR (ERN status — verify) | L4: Partial (rare epilepsy/ID services) | M4: Competitor-trial site — displaceable/trial-ready; Aspire failure (Sep 2026) may free capacity.
A5: Germany | B5: 2 | C5: Munich | D5: LMU Klinikum — Dr. von Haunersches Kinderspital | E5: Pädiatrische Neurologie, Entwicklungsneurologie und Sozialpädiatrie | F5: Dr Lena Manssen; Dr Christine Makowski (review authors); REVEAL/Aspire PI: Not publicly identified — verify locally | G5: First EU REVEAL (ION582 Ph3) site activated (Apr 2026); Aspire (GTX-102) site; authors of 2025 AS precision-medicine review | H5: No | I5: Yes — disease (Manssen et al. 2025); ION582 trial site; competitor trial site | J5: Site (REVEAL; Aspire) | K5: Verify (ERN ITHACA list) | L5: Partial — not confirmed as a named AS clinic | M5: Highest-value German ION582 site. Tier 1 upgrade blocked only by absent P1 / unverified P4.
A6: Germany | B6: 2 | C6: Leipzig | D6: Universitätsklinikum Leipzig | E6: Neuropädiatrie (Klinik für Kinder- und Jugendmedizin); Institut für Humangenetik; Zentrum für Seltene Erkrankungen | F6: Prof Johannes R. Lemke; Dr Ilona Krey; Dr Andreas Merkenschlager; Dr Janina Gburek-Augustat | G6: GTX-102 Ph1/2 and Aspire site; co-authors of 2025 AS precision-medicine review | H6: No | I6: Yes — disease (Manssen et al. 2025); competitor trial (GTX-102 Ph1/2, Aspire) | J6: Site (GTX-102 Ph1/2; Aspire) | K6: Verify (ERN ITHACA / EpiCARE list) | L6: Partial (Rare-disease centre) | M6: Competitor-trial PI pool; strong genetics/DEE research footprint.
A7: Germany | B7: 2 | C7: Hamburg | D7: Universitätsklinikum Hamburg-Eppendorf (UKE) | E7: Klinik für Kinder- und Jugendmedizin — Arbeitsgruppe Neuropädiatrie | F7: Prof Jonas Denecke (neuropaediatrics lead); GTX-102 site PI: Not publicly identified — verify locally | G7: GTX-102 Ph1/2 and Aspire site | H7: No | I7: Yes — competitor trial (GTX-102 Ph1/2, Aspire) | J7: Site (GTX-102 Ph1/2; Aspire) | K7: Verify (ERN list) | L7: No (epilepsy/neuromuscular/TSC focus) | M7: Competitor-trial site; trial-ready IT-dosing infrastructure.
A8: Germany | B8: 3 | C8: Aachen | D8: Universitätsklinikum Aachen — MZEB | E8: Angelman Zentrum Aachen (ASF clinic; adults) | F8: Dr Andrea Maier (coordinator) | G8: Orphanet-listed AS expert centre for adults; ASF clinic | H8: No | I8: No | J8: No | K8: No | L8: Yes (Angelman Zentrum Aachen) | M8: Adult transition / Cohort-2-type population; not research-active per public sources.
A9: Italy | B9: 1 | C9: Pisa | D9: Azienda Ospedaliero-Universitaria Pisana / IRCCS Fondazione Stella Maris | E9: UO Neurologia dello Sviluppo (Stella Maris) with AOUP Phase 1 Unit | F9: Prof Roberta Battini (HALOS PI) | G9: Only Italian HALOS (ION582 Ph1/2) site; national PI; REVEAL site | H9: No | I9: Yes — ION582 trial (HALOS PI) | J9: Coordinator (qualified — sole national HALOS PI) | K9: Verify (ERN ITHACA list) | L9: Partial (developmental neurology unit) | M9: ION582 evidence partner. Tier 1 via P3 national-lead substitution; P1 absent (no Italian AS guideline). See Verification_Flags.
A10: Italy | B10: 2 | C10: Milan | D10: Fondazione IRCCS Istituto Neurologico Carlo Besta | E10: Dip. Neuroscienze Pediatriche — Neurologia dello sviluppo / NPI 2 Epilettologia | F10: Dr Chiara Pantaleoni; Dr Tiziana Granata; Dr Giovanna Zorzi (dept director) | G10: REVEAL and Aurora site; listed national AS diagnosis & care centre | H10: No | I10: Yes — ION582 trial site; competitor trial (Aurora) | J10: Site (REVEAL; Aurora) | K10: National analogue: malattierare.gov.it centre (ERN status — verify) | L10: Partial (AS listed under developmental neurology)
A11: Italy | B11: 2 | C11: Rome | D11: Ospedale Pediatrico Bambino Gesù (IRCCS) | E11: Neuropsichiatria / Neurologia pediatrica | F11: REVEAL PI: Not publicly identified — verify locally | G11: REVEAL site; Aurora 'Rome clinical trial site' (institution unnamed on registry) | H11: No | I11: Yes — ION582 trial site | J11: Site (REVEAL) | K11: Verify (ERN ITHACA list) | L11: Partial (AS disease page)
A12: Italy | B12: 2 | C12: Conegliano (TV) | D12: Associazione La Nostra Famiglia — IRCCS Eugenio Medea | E12: Neurophysiology / rehabilitation | F12: Dr Paolo Bonanni | G12: REVEAL site; long-standing OR.S.A.-identified AS rehabilitation centre | H12: No | I12: Yes — ION582 trial site | J12: Site (REVEAL) | K12: Verify | L12: Yes (AS multidisciplinary rehab pathway)
A13: Italy | B13: 2 | C13: Florence | D13: AOU Meyer IRCCS | E13: Neurologia pediatrica | F13: Aurora PI: Not publicly identified — verify locally | G13: Aurora (GTX-102) site | H13: No | I13: Yes — competitor trial (Aurora) | J13: Site (Aurora) | K13: Verify (ERN EpiCARE/ITHACA) | L13: No | M13: Competitor-trial site.
A14: Italy | B14: 3 | C14: Milan | D14: IRCCS Istituto Auxologico Italiano | E14: Genetica clinica e Laboratorio di Biologia Molecolare | F14: Dr Silvia Russo | G14: OR.S.A. reference centre; AS molecular diagnostics | H14: No | I14: No | J14: No | K14: No | L14: Partial (diagnostic lab) | M14: Diagnostic reference lab.
A15: Italy | B15: 3 | C15: Como | D15: ASST Lariana — Ospedale Sant'Anna | E15: UOC Pediatria | F15: Dr Angelo Selicorni | G15: OR.S.A. reference centre (genetic syndromes) | H15: No | I15: No | J15: No | K15: No | L15: Partial
A16: Italy | B16: 3 | C16: Brescia | D16: ASST Spedali Civili di Brescia | E16: Neuropsichiatria Infantile | F16: Prof Elisa Fazzi | G16: OR.S.A. reference centre | H16: No | I16: No | J16: No | K16: No | L16: Partial
A17: Italy | B17: 3 | C17: Novara | D17: AOU Maggiore della Carità | E17: Neuropsichiatria Infantile | F17: Dr Maurizio Viri | G17: OR.S.A. reference centre | H17: No | I17: No | J17: No | K17: No | L17: Partial
A18: Italy | B18: 3 | C18: Milan | D18: Ospedale Fatebenefratelli e Oftalmico | E18: Neurologia Pediatrica — CREI (Centro Regionale Epilettologia Infantile) | F18: Dr Antonino Romeo | G18: OR.S.A. reference centre (epilepsy) | H18: No | I18: No | J18: No | K18: No | L18: Partial
A19: Italy | B19: 3 | C19: Alessandria | D19: Ospedale Infantile 'C. Arrigo' | E19: Neuropsichiatria Infantile | F19: Dr Maurizio Cremonte | G19: OR.S.A. reference centre | H19: No | I19: No | J19: No | K19: No | L19: Partial
A20: Spain | B20: 1 | C20: Sabadell | D20: Corporació Sanitària Parc Taulí — Hospital de Sabadell | E20: Unitat de Síndrome d'Angelman / Unitat de Malalties Minoritàries (XUEC) | F20: Dra Ana Roche Martínez (clinic head; TANGELO PI) | G20: First EU REVEAL site (Apr 2026); Aspire site; TANGELO PI and Nat Med 2025 co-author; ASF-recognised clinic (Mar 2025); ~140 AS patients | H20: No | I20: Yes — disease; competitor trial (TANGELO Nat Med 2025; Aspire); ION582 trial site | J20: Coordinator (qualified — TANGELO national PI) / Site (REVEAL; Aspire) | K20: National analogue: XUEC (Catalan expert unit network) — ERN status verify | L20: Yes (ASF clinic; Angelman unit) | M20: Strongest Spanish anchor. Hosted first European AS workshop (2023).
A21: Spain | B21: 2 | C21: Esplugues de Llobregat (Barcelona) | D21: Hospital Sant Joan de Déu | E21: Neurologia pediàtrica | F21: Dra Mercedes Serrano | G21: REVEAL site; Aspire site; TANGELO Nat Med 2025 co-author | H21: No | I21: Yes — competitor trial (TANGELO Nat Med 2025; Aspire); ION582 trial site | J21: Site (REVEAL; Aspire) | K21: Verify (ERN list) | L21: Partial | M21: Tier 1 candidate if ERN HCP status verified.
A22: Spain | B22: 2 | C22: Majadahonda (Madrid) | D22: Hospital Universitario Puerta de Hierro Majadahonda | E22: Unidad de Angelman (consulta monográfica since 2012) — Neuropediatría | F22: Dra Gemma Iglesias Escalera; Dr Julián Lara Herguedas; Dra María Lorenzo Ruiz; Dra Rosario Cazorla Calleja | G22: Aspire site; ~125 AS patients (~25% of Spain); FAST-funded biomarker/natural-history project (2024) | H22: No | I22: Yes — competitor trial (Aspire) | J22: Site (Aspire) | K22: Verify | L22: Yes (Unidad de Angelman)
A23: Spain | B23: 2 | C23: Seville | D23: Hospital Universitario Virgen del Rocío | E23: Neuropediatría | F23: Aspire PI: Not publicly identified — verify locally | G23: Aspire site | H23: No | I23: Yes — competitor trial (Aspire) | J23: Site (Aspire) | K23: Verify | L23: No
A24: UK | B24: 1 | C24: Oxford | D24: Oxford University Hospitals NHS FT — John Radcliffe Hospital / University of Oxford | E24: STRONG (Specialised Translational Research Oxford Neuromuscular Group), Dept of Paediatrics | F24: Prof Laurent Servais (CI); Dr Usha Kini (PI); Dr Theodora Markati | G24: HALOS, REVEAL and Aurora site; UK AS Natural History Study (CI/PI) | H24: No | I24: Yes — ION582 trial site; competitor trial (Aurora); natural history | J24: Coordinator (UK AS Natural History Study CI) | K24: N/A (post-Brexit) — national trial-unit designation | L24: Partial (natural-history programme) | M24: ION582 evidence partner in UK. Tier 1 via P3 coordinator + national analogue for P4.
A25: UK | B25: 2 | C25: London | D25: Great Ormond Street Hospital for Children NHS FT | E25: Neurology / clinical trials | F25: REVEAL PI: Not publicly identified — verify locally | G25: REVEAL site | H25: No | I25: Yes — ION582 trial site | J25: Site (REVEAL) | K25: N/A (post-Brexit) | L25: No
A26: UK | B26: 2 | C26: Manchester | D26: Manchester Centre for Genomic Medicine (MFT) | E26: Specialist Angelman Syndrome clinic | F26: Prof Jill Clayton-Smith; Dr Dan Hindley | G26: Consensus diagnostic-criteria contributor; AS clinic; ERN ITHACA coordinator role (per AngelmanUK — currency to verify) | H26: Qualified — consensus diagnostic criteria (pre-2021) | I26: Yes — disease (career AS research) | J26: No | K26: N/A (post-Brexit) | L26: Yes (specialist AS clinic) | M26: Diagnostic/clinical anchor; not on ION582 site lists.

Sheet KOL_Roster
A1: Country | B1: KOL | C1: Primary affiliation | D1: Role/Signal | E1: P1 guideline author | F1: P3 trial / registry role | G1: Key publications/datasets (P2) | H1: Presentation at international conferences | I1: Engagement priority | J1: KOL Tier for TOV (score G/P/T/A/S/Sp/Aw)
A2: France | B2: Pr Nadia Bahi-Buisson | C2: Necker-Enfants Malades, Paris | D2: Médecin responsable, CRMR DI & polyhandicaps (Necker site) | E2: No | F2: Institution = HALOS/Aurora site (personal PI role unverified) | G2: Rett/DEE literature (AS-specific 5-y authorship — verify) | H2: Not verified | I2: TIER 2 — engage — verify HALOS PI | J2: Tier 2 (17: 1/3/1/5/3/3/1)
A3: France | B3: Dr Delphine Héron | C3: Pitié-Salpêtrière (AP-HP Sorbonne) | D3: Coordinator, French PNDS Angelman (2021); CRMR DI coordinating centre | E3: Yes — national PNDS | F3: No | G3: PNDS Angelman (HAS 2021) | H3: Not verified | I3: TIER 2 — engage — national anchor | J3: Tier 2 (17: 3/3/1/3/3/3/1)
A4: France | B4: Pr Mathieu Milh | C4: Hôpital de la Timone (AP-HM), Marseille | D4: Chef de service, neurologie pédiatrique; CRMR épilepsies rares | E4: No | F4: Institution = Aurora site (PI unverified) | G4: DEE/epilepsy literature | H4: Not verified | I4: TIER 2 — engage — competitor-trial site | J4: Tier 2 (17: 1/3/1/5/3/3/1)
A5: France | B5: Dr Nathalie Villeneuve | C5: Hôpital de la Timone (AP-HM) | D5: Neuropaediatrician, CRMR épilepsies rares (directory-sourced) | E5: No | F5: No | G5: Not verified | H5: Not verified | I5: TIER 3 — verify AS role | J5: Tier 3 (9: 1/1/1/3/1/1/1)
A6: France | B6: Dr Béatrice Desnous | C6: Hôpital de la Timone (AP-HM) | D6: Neuropaediatrician (directory-sourced) | E6: No | F6: No | G6: Not verified | H6: Not verified | I6: TIER 3 — verify AS role | J6: Tier 3 (9: 1/1/1/3/1/1/1)
A7: Germany | B7: Prof Johannes R. Lemke | C7: Universitätsklinikum Leipzig | D7: Institute of Human Genetics; Center for Rare Diseases | E7: No | F7: Institution = GTX-102 Ph1/2 & Aspire site | G7: Manssen et al. Neuropediatrics 2025 (co-author); extensive DEE genetics | H7: Not verified | I7: TIER 2 — high value — competitor-trial site | J7: Tier 2 (19: 1/5/1/5/3/3/1)
A8: Germany | B8: Dr Andreas Merkenschlager | C8: Universitätsklinikum Leipzig | D8: Division of Neuropaediatrics | E8: No | F8: Institution = GTX-102 Ph1/2 & Aspire site | G8: Manssen et al. 2025 (co-author) | H8: Not verified | I8: TIER 2 — engage — competitor-trial site | J8: Tier 2 (13: 1/3/1/5/1/1/1)
A9: Germany | B9: Dr Christine Makowski | C9: LMU Klinikum — Dr. von Hauner Children's Hospital | D9: Paediatric neurology / developmental medicine | E9: No | F9: Institution = REVEAL & Aspire site (PI unverified) | G9: Manssen et al. 2025 (senior author) | H9: Not verified | I9: TIER 2 — engage — verify REVEAL PI | J9: Tier 3 (11: 1/3/1/3/1/1/1)
A10: Germany | B10: Prof Jonas Denecke | C10: UKE Hamburg | D10: Lead, Neuropaediatrics working group | E10: No | F10: Institution = GTX-102 Ph1/2 & Aspire site (PI unverified) | G10: Not verified (AS) | H10: Not verified | I10: TIER 3 — verify GTX-102 PI | J10: Tier 3 (11: 1/3/1/3/1/1/1)
A11: Germany | B11: Dr Lena Manssen | C11: LMU Klinikum — Dr. von Hauner Children's Hospital | D11: Paediatric neurology (corresponding author) | E11: No | F11: Institution = REVEAL & Aspire site (PI unverified) | G11: Manssen et al. 2025 (first/corresponding) | H11: Not verified | I11: TIER 3 — engage — verify REVEAL role | J11: Tier 3 (9: 1/3/1/1/1/1/1)
A12: Germany | B12: Dr Ilona Krey | C12: Universitätsklinikum Leipzig | D12: Institute of Human Genetics | E12: No | F12: No | G12: Manssen et al. 2025 (joint first author) | H12: Not verified | I12: TIER 3 | J12: Tier 3 (9: 1/3/1/1/1/1/1)
... A45: UK | B45: Dr Dan Hindley | C45: Manchester Centre for Genomic Medicine | D45: Co-lead, specialist AS clinic | E45: No | F45: No | G45: Not verified | H45: Not verified | I45: TIER 3 | J45: Tier 3 (9: 1/1/1/3/1/1/1)

Sheet Tier_Counts
A1: Centres × Country × Tier
A2: Country | B2: Tier 1 | C2: Tier 2 | D2: Tier 3 | E2: Tier 4 | F2: Total enumerated | G2: Notes
A3: France | B3: =COUNTIFS(Country_Centres!$A$2:$A$26,$A3,Country_Centres!$B$2:$B$26,1) -> 0 | C3: =COUNTIFS(Country_Centres!$A$2:$A$26,$A3,Country_Centres!$B$2:$B$26,2) -> 3 | D3: =COUNTIFS(Country_Centres!$A$2:$A$26,$A3,Country_Centres!$B$2:$B$26,3) -> 0 | E3: =COUNTIFS(Country_Centres!$A$2:$A$26,$A3,Country_Centres!$B$2:$B$26,4) -> 0 | F3: =SUM(B3:E3) -> 3 | G3: No Tier 1: Necker (HALOS) and Pitié (PNDS) split the P3/P1 signals.
A4: Germany | B4: =COUNTIFS(Country_Centres!$A$2:$A$26,$A4,Country_Centres!$B$2:$B$26,1) -> 0 | C4: =COUNTIFS(Country_Centres!$A$2:$A$26,$A4,Country_Centres!$B$2:$B$26,2) -> 3 | D4: =COUNTIFS(Country_Centres!$A$2:$A$26,$A4,Country_Centres!$B$2:$B$26,3) -> 1 | E4: =COUNTIFS(Country_Centres!$A$2:$A$26,$A4,Country_Centres!$B$2:$B$26,4) -> 0 | F4: =SUM(B4:E4) -> 4 | G4: No Tier 1: LMU (first EU REVEAL site) is the anchor candidate.
A5: Italy | B5: =COUNTIFS(Country_Centres!$A$2:$A$26,$A5,Country_Centres!$B$2:$B$26,1) -> 1 | C5: =COUNTIFS(Country_Centres!$A$2:$A$26,$A5,Country_Centres!$B$2:$B$26,2) -> 4 | D5: =COUNTIFS(Country_Centres!$A$2:$A$26,$A5,Country_Centres!$B$2:$B$26,3) -> 6 | E5: =COUNTIFS(Country_Centres!$A$2:$A$26,$A5,Country_Centres!$B$2:$B$26,4) -> 0 | F5: =SUM(B5:E5) -> 11 | G5: Pisa = ION582 HALOS anchor; dense OR.S.A. Tier 3 network.
A6: Spain | B6: =COUNTIFS(Country_Centres!$A$2:$A$26,$A6,Country_Centres!$B$2:$B$26,1) -> 1 | C6: =COUNTIFS(Country_Centres!$A$2:$A$26,$A6,Country_Centres!$B$2:$B$26,2) -> 3 | D6: =COUNTIFS(Country_Centres!$A$2:$A$26,$A6,Country_Centres!$B$2:$B$26,3) -> 0 | E6: =COUNTIFS(Country_Centres!$A$2:$A$26,$A6,Country_Centres!$B$2:$B$26,4) -> 0 | F6: =SUM(B6:E6) -> 4 | G6: Parc Taulí anchor; 3 of 4 sites ran Aspire (competitor).
A7: UK | B7: =COUNTIFS(Country_Centres!$A$2:$A$26,$A7,Country_Centres!$B$2:$B$26,1) -> 1 | C7: =COUNTIFS(Country_Centres!$A$2:$A$26,$A7,Country_Centres!$B$2:$B$26,2) -> 2 | D7: =COUNTIFS(Country_Centres!$A$2:$A$26,$A7,Country_Centres!$B$2:$B$26,3) -> 0 | E7: =COUNTIFS(Country_Centres!$A$2:$A$26,$A7,Country_Centres!$B$2:$B$26,4) -> 0 | F7: =SUM(B7:E7) -> 3 | G7: Oxford anchor (HALOS/REVEAL/NHS); P4 N/A post-Brexit.
A8: TOTAL | B8: =SUM(B3:B7) -> 3 | C8: =SUM(C3:C7) -> 15 | D8: =SUM(D3:D7) -> 7 | E8: =SUM(E3:E7) -> 0 | F8: =SUM(F3:F7) -> 25
A10: KOLs × Country × Tier
A11: Country | B11: Tier 1 | C11: Tier 2 | D11: Tier 3 | E11: Total enumerated | F11: Notes
A12: France | B12: =COUNTIFS(KOL_Roster!$A$2:$A$45,$A12,KOL_Roster!$J$2:$J$45,"Tier 1*") -> 0 | C12: =COUNTIFS(KOL_Roster!$A$2:$A$45,$A12,KOL_Roster!$J$2:$J$45,"Tier 2*") -> 3 | D12: =COUNTIFS(KOL_Roster!$A$2:$A$45,$A12,KOL_Roster!$J$2:$J$45,"Tier 3*") -> 2 | E12: =SUM(B12:D12) -> 5 | F12: Below 15-KOL minimum; HALOS PI unnamed.
A13: Germany | B13: =COUNTIFS(KOL_Roster!$A$2:$A$45,$A13,KOL_Roster!$J$2:$J$45,"Tier 1*") -> 0 | C13: =COUNTIFS(KOL_Roster!$A$2:$A$45,$A13,KOL_Roster!$J$2:$J$45,"Tier 2*") -> 2 | D13: =COUNTIFS(KOL_Roster!$A$2:$A$45,$A13,KOL_Roster!$J$2:$J$45,"Tier 3*") -> 8 | E13: =SUM(B13:D13) -> 10 | F13: Mostly review co-authors; trial PIs unnamed.
A14: Italy | B14: =COUNTIFS(KOL_Roster!$A$2:$A$45,$A14,KOL_Roster!$J$2:$J$45,"Tier 1*") -> 0 | C14: =COUNTIFS(KOL_Roster!$A$2:$A$45,$A14,KOL_Roster!$J$2:$J$45,"Tier 2*") -> 7 | D14: =COUNTIFS(KOL_Roster!$A$2:$A$45,$A14,KOL_Roster!$J$2:$J$45,"Tier 3*") -> 5 | E14: =SUM(B14:D14) -> 12 | F14: Battini is the ION582 apex KOL.
A15: Spain | B15: =COUNTIFS(KOL_Roster!$A$2:$A$45,$A15,KOL_Roster!$J$2:$J$45,"Tier 1*") -> 0 | C15: =COUNTIFS(KOL_Roster!$A$2:$A$45,$A15,KOL_Roster!$J$2:$J$45,"Tier 2*") -> 3 | D15: =COUNTIFS(KOL_Roster!$A$2:$A$45,$A15,KOL_Roster!$J$2:$J$45,"Tier 3*") -> 9 | E15: =SUM(B15:D15) -> 12 | F15: Two TANGELO (competitor) authors.
A16: UK | B16: =COUNTIFS(KOL_Roster!$A$2:$A$45,$A16,KOL_Roster!$J$2:$J$45,"Tier 1*") -> 0 | C16: =COUNTIFS(KOL_Roster!$A$2:$A$45,$A16,KOL_Roster!$J$2:$J$45,"Tier 2*") -> 3 | D16: =COUNTIFS(KOL_Roster!$A$2:$A$45,$A16,KOL_Roster!$J$2:$J$45,"Tier 3*") -> 2 | E16: =SUM(B16:D16) -> 5 | F16: Below minimum; GOSH PI unnamed.
A17: TOTAL | B17: =SUM(B12:B16) -> 0 | C17: =SUM(C12:C16) -> 18 | D17: =SUM(D12:D16) -> 26 | E17: =SUM(E12:E16) -> 44
A19: Cross-cuts
A20: Measure | B20: Count
A21: Centres — hosting a P1 guideline author (incl. qualified) | B21: =COUNTIF(Country_Centres!H2:H26,"Yes*")+COUNTIF(Country_Centres!H2:H26,"Qualified*") -> 2
A22: Centres — P2 disease/trial publication or trial authorship | B22: =COUNTIF(Country_Centres!I2:I26,"Yes*") -> 17
A23: Centres — P2 ION582 trial involvement | B23: =COUNTIF(Country_Centres!I2:I26,"*ION582*") -> 10
A24: Centres — P2 competitor-trial involvement | B24: =COUNTIF(Country_Centres!I2:I26,"*competitor*") -> 12
A25: Centres — P3 coordinator role | B25: =COUNTIF(Country_Centres!J2:J26,"Coordinator*") -> 3
A26: Centres — listed as P3 sites | B26: =COUNTIF(Country_Centres!J2:J26,"*Site*") -> 14
A27: Centres — P4 HCP / national analogue confirmed | B27: =COUNTIF(Country_Centres!K2:K26,"Yes*")+COUNTIF(Country_Centres!K2:K26,"National analogue*") -> 5
A28: Centres — explicit P5 AS programme | B28: =COUNTIF(Country_Centres!L2:L26,"Yes*") -> 5
A29: KOLs — guideline authorship (incl. qualified) | B29: =COUNTIF(KOL_Roster!E2:E45,"Yes*")+COUNTIF(KOL_Roster!E2:E45,"Qualified*") -> 2
A30: KOLs — clinical-trial publications / roles | B30: =COUNTIF(KOL_Roster!G2:G45,"*Nat Med*")+COUNTIF(KOL_Roster!G2:G45,"*HALOS*") -> 3
A31: KOLs — disease publications (verified) | B31: =COUNTA(KOL_Roster!G2:G45)-COUNTIF(KOL_Roster!G2:G45,"Not verified*") -> 20
A32: KOLs — international presentations (verified) | B32: =COUNTA(KOL_Roster!H2:H45)-COUNTIF(KOL_Roster!H2:H45,"Not verified*") -> 1

Sheet Infrastructure
A1: Domain | B1: Capability | C1: Minimum requirement | D1: Typical Tier 1-2 coverage | E1: Notes / failure modes
A2: Diagnostics | B2: Molecular confirmation | C2: Methylation analysis (MS-MLPA) then UBE3A sequencing; genotype class (deletion / UBE3A mutation / UPD / ICD) documented | D2: Universal via genetics departments | E2: ION582 REVEAL enrols deletion or UBE3A-mutation only — UPD/ICD patients excluded, so genotype must be on file.
A3: Diagnostics | B3: EEG | C3: Routine and sleep EEG with AS-pattern recognition; delta-power quantification capability for biomarker work | D3: Tier 1–2 neurophysiology | E3: EEG delta power is the leading pharmacodynamic biomarker across UBE3A-ASO programmes (TANGELO).
A4: Severity assessment | B4: Developmental / outcome measures | C4: Bayley-4 (expressive communication, cognition), Vineland, CGI-AS administered by trained raters | D4: Trial sites (HALOS/REVEAL/Aspire/TANGELO) | E4: REVEAL primary endpoint is Bayley-4 expressive communication; rater training is a site-readiness gate.
A5: Treatment (SoC) | B5: Multidisciplinary symptomatic care | C5: Neurology/epilepsy, sleep, GI/nutrition, orthopaedics, ophthalmology, AAC/communication, behaviour — per Duis 2022 / French PNDS | D5: Strong at Parc Taulí, Puerta de Hierro, Manchester, Necker | E5: Seizure control and anaesthesia safety are pre-requisites for intrathecal dosing.
A6: Treatment — DIFFERENTIATING | B6: Intrathecal administration | C6: Repeat lumbar puncture under sedation/anaesthesia without intubation; paediatric anaesthesia; day-case capacity | D6: All ASO trial sites; NOT typical at Tier 3 | E6: THE key infrastructure gate for ION582 launch. Tier 3 OR.S.A./directory centres likely need hub-and-spoke referral.
A7: Rehabilitation / chronic | B7: Lifelong therapy & adult transition | C7: Physio, OT, AAC; adult services | D7: Weak for adults (Aachen MZEB, Puerta de Hierro adult neurology, Oxford adult cohort) | E7: REVEAL Cohort 2 (18–50 y) needs adult-capable sites.
A8: Future-state (a) | B8: ION582 administration capability | C8: IT bolus delivery + monitoring per label (dose/interval to confirm at approval) | D8: Existing HALOS/REVEAL sites: Oxford, GOSH, Necker, Pisa, Besta, OPBG, Medea, LMU, Parc Taulí, SJD | E8: Asset overlay: ION582's addressable base extends beyond its own trial sites to competitor ASO sites (Aspire/Aurora/TANGELO) that already hold IT-dosing, Bayley rating and EEG infrastructure — Aspire's failure (Sep 2026) makes these sites displaceable.
A9: Future-state (b) | B9: RWE / registry participation | C9: Contribution to natural-history datasets (UK NHS, ASF International Clinic Network/LADDER, Global AS Registry) | D9: Oxford, Parc Taulí, Puerta de Hierro | E9: No pan-EU clinical AS registry yet; ASF/Erasmus network is the emerging vehicle.

Sheet Sources_Caveats
A1: Authoritative source | B1: URL / reference | C1: What it provides
A2: P1 — International AS standards of care (Duis et al. 2022) | B2: https://doi.org/10.1002/mgg3.1843 | C2: Consensus SoC; PMID 35150089; author list (no EU4+UK authors)
A3: P1 — Europe PMC record (Duis et al.) | B3: https://europepmc.org/articles/PMC8922964/ | C3: Author affiliations
A4: P1 — France PNDS Syndrome d'Angelman (HAS, 2021) | B4: https://www.has-sante.fr/jcms/p_3300847/fr/syndrome-d-angelman | C4: National protocol; coordinated by Dr D. Héron
A5: P1 — PNDS argumentaire (HAS PDF) | B5: https://www.has-sante.fr/upload/docs/application/pdf/2021-11/argumentaire_pnds_angelman_vf.pdf | C5: Coordinator / CRMR attribution
A6: P2 — TANGELO rugonersen Ph1 (Hipp et al., Nat Med 2025) | B6: https://www.nature.com/articles/s41591-025-03784-7 | C6: DOI 10.1038/s41591-025-03784-7; PMID 40646322; NCT04428281
A7: P2 — TANGELO author list | B7: https://www.baylorgenetics.com/publication/the-ube3a-ats-antisense-oligonucleotide-rugonersen-in-children-with-angelman-syndrome-a-phase-1-trial/ | C7: Roche Martínez, Serrano co-authors
A8: P2 — Manssen et al., Precision Medicine in AS (Neuropediatrics 2025) | B8: https://www.thieme-connect.com/products/ejournals/pdf/10.1055/a-2399-0191.pdf | C8: LMU / Leipzig author cohort
A9: P2/P3 — HALOS NCT05127226 | B9: https://clinicaltrials.gov/study/NCT05127226 | C9: ION582 Ph1/2; EU4+UK sites: Necker, Pisa, Oxford
A10: P2/P3 — HALOS site list (ICH GCP mirror) | B10: https://ichgcp.net/clinical-trials-registry/NCT05127226 | C10: Site names
A11: P2/P3 — REVEAL NCT06914609 | B11: https://clinicaltrials.gov/study/NCT06914609 | C11: ION582 Ph3; 80 mg vs control
A12: P3 — REVEAL site list (eichor mirror) | B12: https://eichor.com/study/NCT06914609 | C12: EU4+UK REVEAL sites
... A38: Diagnostics — AS methylation/UBE3A testing (DE lab) | B38: https://dna-diagnostik.hamburg/analysespektrum/angelman-syndrom/ | C38: MS-MLPA → UBE3A sequencing
A40: CAVEATS
A41: Coverage | B41: Registry mirrors list institutions, not PIs; PI attribution is via publications, press releases and patient-organisation pages.
A42: Geography gaps | B42: UK post-Brexit (P4 N/A); no AS national guideline in DE/IT/ES/UK; German Tier 1 absent.
A43: KOL movement | B43: Affiliations change frequently — re-verify before engagement.
A44: Gap-fill disclosure | B44: Directory-sourced names (e.g. Timone staff) carry no verified AS signal and are Tier 3 by default.
A45: Tier 4 | B45: Not enumerated — not requested; AS care concentrates at expert centres.
A46: Trial-readiness checklist | B46: IT dosing under sedation · Bayley-4 raters · EEG · genotype on file · adult services (Cohort 2).
A47: Asset-specific signal | B47: ION582 evidence partners: Battini (Pisa), Oxford STRONG (Servais/Kini), Necker, LMU, Parc Taulí. No public named European endorsers of ION582 identified.
A48: Competitor context | B48: Apazunersen Aspire failed (Sep 2026); rugonersen (Oak Hill Bio) Ph3 BEACON registered; TANGELO EU authors (Roche Martínez, Serrano) are competitor-programme investigators.

Sheet Verification_Flags
A1: # | B1: Sheet | C1: Cell(s) | D1: Item | E1: Finding | F1: Recommended correction | G1: Verdict
A2: 1 | B2: Country_Centres | C2: B (Pisa, Parc Taulí, Oxford) | D2: Tier 1 assignment | E2: No EU4+UK centre meets the strict P1 criterion (no national guideline in IT/ES/UK; Duis 2022 has no EU4+UK authors). Tier 1 granted via P3 national-lead substitution. | F2: Confirm acceptance of substitution or downgrade to Tier 2. | G2: WORDING
A3: 2 | B3: Country_Centres | C3: K (all EU rows marked 'Verify') | D3: ERN ITHACA HCP status | E3: ERN HCP membership not verified per centre; only Necker CRMR is sourced as ERN ITHACA-affiliated. | F3: Check live ERN ITHACA HCP list before use. | G3: PART-UNVERIFIABLE
A4: 3 | B4: Country_Centres | C4: F (Necker, GOSH, OPBG, Meyer, Virgen del Rocío, LMU, UKE, Timone) | D4: Site PI names | E4: Trial site PIs not publicly listed on registry mirrors. | F4: Obtain PI names from CT.gov contacts / Ionis MSLs. | G4: PART-UNVERIFIABLE
A5: 4 | B5: KOL_Roster | C5: Dra Elisabeth Gabau | D5: Affiliation currency | E5: Named by Parc Taulí in Mar 2025 as a historical founder of the service; current role unclear. | F5: Re-verify before outreach. | G5: OUTDATED
A6: 5 | B6: KOL_Roster | C6: Prof Jill Clayton-Smith | D6: ERN ITHACA coordinator claim | E6: AngelmanUK page states ERN ITHACA coordinator role; UK HCPs left ERNs post-Brexit. | F6: Re-verify current ERN role. | G6: OUTDATED
A7: 6 | B7: KOL_Roster | C7: Dr Lena Manssen / Dr Christine Makowski | D7: REVEAL role | E7: LMU is first EU REVEAL site; their trial roles are inferred from institution, not sourced. | F7: Confirm with Ionis / site list. | G7: PART-UNVERIFIABLE
A8: 7 | B8: KOL_Roster | C8: Prof Stefano Vicari | D8: AS signal | E8: Head of OPBG neuropsychiatry; AS-specific role not sourced. | F8: Verify or replace with REVEAL PI. | G8: PART-UNVERIFIABLE
A9: 8 | B9: KOL_Roster | C9: Dra Neus Baena / Dra Belén Ruiz Antorán | D9: Clinician status | E9: Laboratory/pharmacology roles — may not be treating physicians for TOV. | F9: Confirm HCP category before TOV classification. | G9: WORDING
A10: 9 | B10: KOL_Roster | C10: All | D10: Minimum 15 KOLs per country | E10: Only 5 (FR), 10 (DE), 12 (IT), 12 (ES), 5 (UK) traceable names without fabrication. | F10: Gap-fill via hospital directories / MSL field intel. | G10: PART-UNVERIFIABLE
A11: 10 | B11: KOL_Roster | C11: TANGELO co-authors | D11: Independence / compliance | E11: Hipp, Bruenig-Traebert, Fontoura, Hooper, Jagasia, Krishnan, Noci, Schwab, Tillmann, Tjeertes, Vincenzi are Roche/industry-affiliated authors — deliberately excluded from roster. | F11: None — passed. | G11: COMPLIANCE-relevant (passed)
A12: 11 | B12: Infrastructure | C12: Future-state | D12: Drug premise | E12: REVEAL: Ph3, 80 mg vs control, Cohort 1 fully enrolled Jul 2026, readout H2 2027; HALOS 71 enrolled; FDA Breakthrough 2025 — all sourced from Ionis/ASF communications. | F12: None — passed. | G12: VERIFIED
A13: 12 | B13: Infrastructure | C13: Competitor | D13: Competitor premise | E13: Aspire (apazunersen) missed primary & key secondary endpoints (2 Sep 2026); Aurora continuing; rugonersen BEACON Ph3 registered. | F13: None — passed. | G13: VERIFIED
A15: Closing note | B15: Checked and passed: ION582 trial status (HALOS/REVEAL), site lists for HALOS/REVEAL/Aspire/Aurora/GTX-102 Ph1/2, Aspire topline, French PNDS coordinator, TANGELO author affiliations, ASF/XUEC/Orphanet clinic designations. Red-highlighted cells on Country_Centres and KOL_Roster are the only items requiring your decision; nothing was auto-corrected.
