Workbook

Sheet README
A1: EU4+UK Angelman Syndrome Treatment Centres and KOLs — Mapping & Tiering
A3: SCOPE
A4: Title | B4: EU4+UK Angelman Syndrome Treatment Centres and KOLs — Mapping & Tiering
A5: Prepared for | B5: Medical Affairs workstream — obudanersen (ION582, Ionis) (Angelman syndrome)
A6: Geographies | B6: Germany, France, Italy, Spain, United Kingdom (EU4+UK)
A7: Asset phase | B7: Pre-approval (Phase 3 REVEAL NCT06914609 fully enrolled; topline 2H 2027)
A8: Date compiled | B8: 46309
A9: Compiled by | B9: Copilot Cowork (automated, high-effort run) for Ian Pepper
A10: Method | B10: Cross-referenced from public sources (ClinicalTrials.gov / EU CTIS, ERN ITHACA / EpiCARE HCP lists, national guidelines, national AS patient organisations, Orphanet, sponsor communications, PubMed / publisher records). Template: PROMPT_KOL_Centre_Map_v2.
A11: Content | B11: 95 centres (Tiers 1–3) · 97 named KOLs · 150 sources · 92 verification items
A13: TAB GUIDE
A14: README | B14: Scope, five signal pillars, Centre and KOL tier definitions + scoring criteria, critical caveats, asset overlay & facts, gap-fill methodology, how to use.
A15: Country_Centres | B15: Master flat table — one row per Tier 1–3 centre; P1–P5 signal flags; notes with source URLs. Sorted by Country then Tier; autofilter on.
A16: KOL_Roster | B16: Named clinicians/scientists with role, P1/P3 roles, P2 publications, international presentations, engagement priority, the seven KOL scores, formula Total and formula KOL Tier for TOV, plus sources.
A17: Tier_Counts | B17: Centre and KOL country × tier matrices with interpretive notes, plus cross-cut counts — all live COUNTIFS/SUMPRODUCT formulas on the data tabs.
A18: Infrastructure | B18: AS diagnostic, severity-assessment, treatment, chronic-management and future-state (obudanersen IT-ASO) requirements mapped to Tier 1–2 coverage.
A19: Sources_Caveats | B19: Authoritative sources with clickable URLs; caveats (all-geography + per-country); asset & competitor trial footprint (competitor programmes; EU4+UK trial sites).
A20: Verification_Flags | B20: Adversarial QA pass — affiliation currency, independence/compliance, provenance, wording/counts, drug premise; flagged source cells highlighted red on their home sheets (not auto-corrected).
A22: THE FIVE SIGNAL PILLARS (calibrated for Angelman syndrome)
A23: P1 — Consensus 2022 / national guideline author | B23: Guideline authorship — Duis et al. 2022 international consensus standards of care (Mol Genet Genomic Med 10:e1843; doi:10.1002/mgg3.1843; PMID 35150089) plus national guidance: France PNDS Syndrome d'Angelman (CRMR Déficiences intellectuelles de causes rares, HAS, Dec-2021); diagnostic anchor Williams 2006 criteria (PMID 16470747). No national AS guideline identified for DE/IT/ES/UK — country-level P1 relies on consensus authorship.
A24: P2 — AS publications / ION582 or competitor trial (5y) | B24: Publication & trial authorship — AS peer-reviewed output 2021–2026 and investigator roles on obudanersen HALOS (NCT05127226)/REVEAL (NCT06914609)/CHAMPION (NCT07782827) and competitor programmes: apazunersen Ph1/2 (NCT04259281) & Aspire (NCT06617429; failed Sep-2026), rugonersen TANGELO (NCT04428281; Nat Med 2025), gaboxadol NEPTUNE (NCT04106557; PMID 37639777).
A25: P3 — AS registry / trial-network coord/site | B25: Registry / trial-network participation — Global Angelman Syndrome Registry (angelmanregistry.info), LADDER via the ASF International Clinic Network (Erasmus MC partner, Jan-2026), national registries (e.g. Italian RISA/FROM), and REVEAL/HALOS/Aspire/TANGELO site networks per ClinicalTrials.gov.
A26: P4 — ERN ITHACA / EpiCARE HCP | B26: Reference-network membership — ERN ITHACA HCP (primary) and ERN EpiCARE HCP (secondary), per EC ERN Service Directory; UK = N/A (post-Brexit) with NHS highly specialised/regional genetics services as analogue; national analogues FR CRMR/CCMR (DéfiScience/AnDDI-Rares), ES CSUR, DE ZSE, IT regional rare-disease networks.
A27: P5 — Angelman clinic / programme | B27: Disease programme — named multidisciplinary Angelman clinic (Yes) or broader ID/neurogenetics/rare-epilepsy programme (Partial), sourced from national patient organisations (Angelman e.V., AFSA, OR.S.A., ASA, AngelmanUK/FAST UK) and hospital pages.
A29: CENTRE TIER DEFINITIONS (template §3)
A30: Tier 1 — Anchor / reference | B30: Definition: hosts a P1 guideline author OR a P3 registry coordinator, AND is a P4 reference-network HCP (or its national equivalent), AND carries the P2 publication signal (disease- or asset-/competitor-trial authorship in the last ~5 years). Role in plan: first-wave KOL engagement; advisory-board core; RWE and observational lead candidates; the asset's likely evidence partners.
A31: Tier 2 — National referral | B31: Definition: a P4 HCP with the relevant P5 programme, OR a P3 participating site; university hospital with full critical/specialist care and disease-relevant diagnostics; recurring P2 authorship on the relevant literature. Role in plan: second-wave outreach; regional referral hubs.
A32: Tier 3 — Tertiary capable | B32: Definition: national/regional reference centre or large university hospital with the core treatment infrastructure but typically not research-active in the disease. Role in plan: launch-phase distribution; HCP education; not advisory core.
A33: Tier 4 — Community / acute presentation | B33: Definition: district/general hospitals where patients first present and receive supportive care, then refer on. Role in plan: enumerate only if explicitly asked (too dispersed) — NOT enumerated in this build (not requested). Matters for case-finding, patient pathway and pharmacovigilance — address via national-society / patient-organisation channels, not individual outreach.
A34: Calibration note | B34: Angelman syndrome is a chronic, managed disease: care concentrates at reference / genetics / neuropaediatric centres, so the acute-presentation dispersion caveat is omitted.
A36: KOL TIER DEFINITIONS & SCORING CRITERIA (template §3)
A37: Purpose | B37: Evaluate and classify each identified physician (KOL) by level of expertise, influence and contribution to the therapeutic area.
A38: Step 1 — Guideline authorship | B38: 1 point — contributor to local protocols or internal standards; co-author of minor/regional guidelines 3 points — lead/co-author of national guidelines; contributor to multicentre consensus statements 5 points — lead/co-author of international or globally influential guidelines
A39: Step 1 — Publications | B39: 1 point — ≥3 publications (any authorship) in relevant peer-reviewed journals 3 points — ≥5 publications in reputable journals (last 7 years) 5 points — ≥5 publications as first/last author (last 7 years)
A40: Step 1 — Clinical trials | B40: 1 point — participant or site investigator in local/national trials 3 points — national PI or investigator in multi-country/regional trials (last 7 years) 5 points — lead/site PI in large international or pivotal trials influencing practice/regulation
A41: Step 1 — Academic appointment | B41: 1 point — specialist physician; working/research group member; completed specialist training 3 points — senior physician; associate professor; research group member; retired department head 5 points — department head; research group leader; emeritus professor
A42: Step 1 — Society roles | B42: 1 point — member of local/regional society 3 points — committee/board member in national society 5 points — executive leadership in major national/international societies
A43: Step 1 — Speaker engagement | B43: 1 point — occasional local/regional speaker 3 points — regular invited speaker at national conferences 5 points — keynote/plenary speaker at major international congresses
A44: Step 1 — Awards | B44: 1–2 points depending on calibre of award (0 if none evidenced)
A45: Step 2 — Scoring rules | B45: Evaluate each physician independently across all categories; assign 1, 3 or 5 points per category on best fit; use the highest level fully supported by evidence; do not infer or assume achievements; if information is limited assign the lowest reasonable score (default 1); prioritise recent (last 5–7 years) and verifiable contributions.
...

Sheet Country_Centres
A1: Country_Centres — EU4+UK Angelman syndrome treatment centres (Tiers 1–3), obudanersen (ION582) mapping
A2: Country | B2: Tier | C2: City | D2: Centre / Hospital | E2: Unit / Department | F2: KOL / Lead clinician(s) | G2: Role / Affiliation signal | H2: P1 — Consensus 2022 / national guideline author | I2: P2 — AS publications / ION582 or competitor trial (5y) | J2: P3 — AS registry / trial-network coord/site | K2: P4 — ERN ITHACA / EpiCARE HCP | L2: P5 — Angelman clinic / programme | M2: Notes
A3: France | B3: 1 | C3: Paris | D3: AP-HP Sorbonne Université — Groupe Hospitalier Pitié-Salpêtrière | E3: Département de Génétique (UF Génétique clinique) — CRMR coordonnateur Déficiences Intellectuelles de causes rares (Filière DéfiScience); Neurologie (adult AS); Pédopsychiatrie | F3: Dr Delphine Héron; Dr Perrine Charles; Pr Angèle Consoli | G3: PNDS Angelman coordinator (Dr Héron) and national CRMR DI coordinator; ERN ITHACA Paris consortium (DéfiScience axis); 3 AFSA Conseil Médical et Scientifique members on site | H3: Yes — national guideline (PNDS Syndrome d'Angelman, Nov 2021, CRMR DI de causes rares) — coordinating centre/author (Héron) | I3: Yes — disease (qualified): PNDS + argumentaire 2021 (systematic review of 249 studies) authored by this CRMR; individual AS peer-reviewed papers 2021–26 not verified in this pass | J3: No — no French site on REVEAL (NCT06914609; 41 sites, none in FR) or Aspire (NCT06617429; EU sites DE/PL/ES); national registry (BNDMR) participation not verified | K3: Yes — ITHACA (AP-HP Paris consortium) + national CRMR coordinator (DéfiScience) | L3: Yes — national AS expertise hub (PNDS-issuing CRMR; adult AS follow-up via neurology; AFSA CMS) | M3: Natural FR advisory-board anchor and ION582 evidence-partner candidate. Tier 1 is provisional: P2 rests on the PNDS/argumentaire, not verified peer-reviewed AS papers. PNDS contact: UF de Génétique clinique, 47-83 bd de l'Hôpital, Paris 13. CRMR DI also spans Hôpital Armand-Trousseau. Sources: https://www.has-sante.fr/upload/docs/application/pdf/2021-11/pnds_angelman_vf_.doc.pdf; https://www.has-sante.fr/upload/docs/application/pdf/2021-11/argumentaire_pnds_angelman_vf.pdf; https://www.has-sante.fr/jcms/p_3300847/fr/syndrome-d-angelman; https://ern-ithaca.eu/about-us/expert-centers/ern-ithaca-paris-center-robert-debre-university-hospital/; https://www.angelman-afsa.org/afsa/son-equipe/conseil-medical-et-scientifique/afsa/son-equipe/conseil-medical-et-scientifique/le-conseil-medical-et-scientifique
A4: France | B4: 1 | C4: Paris | D4: AP-HP Hôpital Necker-Enfants Malades | E4: Neuropédiatrie — CRMR DI de causes rares et polyhandicap; CRéER (Centre de référence épilepsies rares) site constitutif; Génétique clinique | F4: Dr Nadia Bahi-Buisson; Dr Marie Hully; Pr Rima Nabbout; Dr Marlène Rio | G4: French coordinating centre for obudanersen Phase 1/2 HALOS (ION582-CS1). Dr Bahi-Buisson is the coordinating investigator and also coordinates the GTX-102 Phase 2 basket study (GTX-102-CL210). The centre also has EpiCARE (HCP coordinator Nabbout), ITHACA Paris and former AFSA CMS president (Hully) signals. | H4: No (individual PNDS authorship not verified; AFSA CMS, chaired by Hully, finalised the PNDS 2021) | I4: Yes — ION582 trial (HALOS NCT05127226) + Yes — competitor trial (GTX-102 Ph1/2 NCT04259281 site; GTX-102 Ph2 basket CL210 national coordinator; GTX-102 LTE CL302 recruiting site) | J4: Site — ION582 HALOS (French national coordinating centre per AP-HP trial registry; opened Jun-2023). Also Site — competitor (GTX-102 Ph1/2, Ph2 basket, LTE). Not a REVEAL site. | K4: Yes — ITHACA+EpiCARE | L4: Yes — AS explicitly in CRéER rare-epilepsy scope; CRMR DI/polyhandicap neuropaediatrics | M4: Re-tiered 2→1. The ITHACA+EpiCARE (P4) and HALOS plus GTX-102 trial authorship/PI roles (P2) criteria are met. The P1/P3-coordinator arm is met only by reading 'national coordinating centre of the asset's Ph1/2 trial' as a P3 coordinator role; no registry coordinator or PNDS author is verified here (see flag). This is the only French centre with intrathecal UBE3A-ASO dosing experience (ION582 and GTX-102), making it the primary ION582 evidence partner, REVEAL/CHAMPION site candidate and HALOS-LTE continuity site. HALOS is active, not recruiting; the AP-HP entry is closed to inclusion. Sources: https://www.aphp.fr/registre-des-essais-cliniques/etude-visant-evaluer-la-securite-la-tolerance-la-pharmacocinetique-et; https://eichor.com/study/NCT05127226; https://www.fastfrance.org/dossier-angelman/ionis-syndrome-dangelman/; https://www.aphp.fr/registre-des-essais-cliniques/etude-en-ouvert-de-phase-2-de-type-panier-visant-evaluer-linnocuite; https://hopital-broca.aphp.fr/registre-des-essais-cliniques/etude-dextension-long-terme-portant-sur-la-securite-demploi-et-65; https://clinicaltrials.gov/study/NCT04259281; https://epi-care.eu/hospitals/necker-enfants-malades-aphp/; https://maladiesrares-necker.aphp.fr/rare-epilepsies/; https://ern-ithaca.eu/about-us/expert-centers/ern-ithaca-paris-center-robert-debre-university-hospital/
A5: France | B5: 1 | C5: Marseille | D5: AP-HM Hôpital de la Timone Enfants | E5: Neurologie pédiatrique — CRéER coordinating centre (épilepsies rares) + CRMR DI/polyhandicap site | F5: Dr Béatrice Desnous; Pr Mathieu Milh | G5: Pr Milh is the national coordinating investigator of the GTX-102 long-term extension (GTX-102-CL302). The centre was a GTX-102 Ph1/2 site and is the CRéER coordinating centre; Dr Desnous is current AFSA CMS president. | H5: No (PNDS authorship not verified) | I5: Yes — competitor trial (GTX-102 Ph1/2 NCT04259281 site; GTX-102 LTE CL302 national coordinator) | J5: Coordinator (national) — competitor GTX-102 LTE CL302. Also Site — competitor (GTX-102 Ph1/2). No ION582 site. | K5: National CRMR (CRéER coordinating centre; CRMR DI site). ERN EpiCARE/ITHACA membership not verified. | L5: Yes — AS-engaged neuropaediatrics (AFSA CMS presidency) within rare-epilepsy/DI reference programme | M5: Re-tiered 2→1 on the competitor-trial national coordinator role, the national CRMR coordinator role (P4 national analogue per brief) and competitor-trial P2. Displaceable, intrathecal-ASO-experienced site: high value for REVEAL/CHAMPION expansion now that Aspire has failed (2-Sep-2026). The LTE status after Aspire is uncertain, so verify. Confirm ERN membership. Sources: https://www.angelman-afsa.org/afsa/son-equipe/conseil-medical-et-scientifique/afsa/son-equipe/conseil-medical-et-scientifique/le-conseil-medical-et-scientifique; https://stxbp1eu.org/france/; https://kcnq2francedeveloppement.fr/pole-recherche/; https://maladiesrares-necker.aphp.fr/rare-epilepsies/; https://hopital-broca.aphp.fr/registre-des-essais-cliniques/etude-dextension-long-terme-portant-sur-la-securite-demploi-et-65; https://clinicaltrials.gov/study/NCT04259281
A6: France | B6: 2 | C6: Paris | D6: AP-HP Hôpital Robert-Debré | E6: Département de Génétique — CRMR coordonnateur CLAD Île-de-France (AnDDI-Rares); ERN ITHACA EU coordinating centre | F6: Pr Alain Verloes; Dr David Germanaud | G6: ERN ITHACA EU coordinator (Verloes, since 2018); CLAD-IDF coordinator; ITHACA Paris consortium (Germanaud, DéfiScience axis) | H6: No (not verified as PNDS contributor) | I6: No AS-specific 2021–26 publication verified | J6: No — no French site on REVEAL (NCT06914609; 41 sites, none in FR) or Aspire (NCT06617429; EU sites DE/PL/ES) | K6: Yes — ITHACA (EU coordinating centre) | L6: Partial — developmental anomalies / neurodevelopmental genetics programme | M6: European-network gateway (ITHACA guidance/endorsement, CPMS). Not AS-research-active on current evidence; engage for network-level RWE and ERN guidance. Sources: https://ern-ithaca.eu/about-us/expert-centers/ern-ithaca-paris-center-robert-debre-university-hospital/; https://ern-ithaca.eu/about-us/who-we-are/; https://robertdebre.aphp.fr/centre-de-reference-des-anomalies-du-developpement-syndromes-malformatif-dile-de-france
A7: France | B7: 2 | C7: Paris | D7: AP-HP Sorbonne Université — Hôpital Armand-Trousseau | E7: Neuropédiatrie & Génétique — CRMR DI de causes rares (site), ITHACA Paris consortium | F7: Dr Stéphanie Valence; Dr Nathalie Dorison | G7: ITHACA Paris consortium (Valence, child neurology); historic AFSA CMS member (Dorison); AFSA CMS psychologist on site | H7: No (not verified) | I7: No AS-specific 2021–26 paper verified | J7: No — no French site on REVEAL (NCT06914609; 41 sites, none in FR) or Aspire (NCT06617429; EU sites DE/PL/ES) | K7: Yes — ITHACA (AP-HP Paris consortium) + CRMR DI site | L7: Partial — DI/neurodevelopmental programme; AS experience via AFSA CMS | M7: Part of the Pitié–Trousseau CRMR DI pairing named in the PNDS contact block. Sources: https://ern-ithaca.eu/about-us/expert-centers/ern-ithaca-paris-center-robert-debre-university-hospital/; https://www.has-sante.fr/upload/docs/application/pdf/2021-11/pnds_angelman_vf_.doc.pdf; https://www.livret-angelman-afsa.org/les-contributeurs; https://www.angelman-afsa.org/afsa/son-equipe/conseil-medical-et-scientifique/afsa/son-equipe/conseil-medical-et-scientifique/le-conseil-medical-et-scientifique
A8: France | B8: 2 | C8: Lyon (Bron) | D8: Hospices Civils de Lyon — Hôpital Femme-Mère-Enfant | E8: Service de génétique — CLAD Sud-Est coordinator; CRDI (DéfiScience); Child Neurology | F8: Dr Massimiliano Rossi | G8: ERN ITHACA Lyon centre lead; CRDI coordinates DéfiScience per ITHACA page; AURAGEN genome platform | H8: No | I8: No AS-specific 2021–26 paper verified | J8: No — no French site on REVEAL (NCT06914609; 41 sites, none in FR) or Aspire (NCT06617429; EU sites DE/PL/ES) | K8: Yes — ITHACA | L8: Partial — ID/neurodevelopment genetics programme | M8: Regional hub for Grenoble, Saint-Étienne, Clermont-Ferrand, Marseille, Nice and Toulon genetics. Sources: https://ern-ithaca.eu/about-us/expert-centers/ern-ithaca-lyon-center/
A9: France | B9: 2 | C9: Dijon | D9: CHU Dijon Bourgogne — Hôpital d'Enfants | E9: Centre de Génétique — CRMR Anomalies du développement; FHU TRANSLAD | F9: Pr Laurence Faivre | G9: ERN ITHACA Dijon centre lead; FHU-TRANSLAD coordination (genomic medicine in developmental disorders) | H9: No | I9: No AS-specific 2021–26 paper verified (NDD episignature co-authorship 2024, PMID 37872275) | J9: No — no French site on REVEAL (NCT06914609; 41 sites, none in FR) or Aspire (NCT06617429; EU sites DE/PL/ES) | K9: Yes — ITHACA | L9: Partial — developmental disorders/ID genetics programme | M9: Strong translational/genomic-medicine infrastructure; potential RWE partner. Sources: https://ern-ithaca.eu/about-us/expert-centers/ern-ithaca-dijon-center/; https://pubmed.ncbi.nlm.nih.gov/37872275/
A10: France | B10: 3 | C10: Brest | D10: CHU de Brest | E10: Neuropédiatrie | F10: Dr Sylviane Peudenier | G10: AFSA CMS president for 7 years (predecessor of Hully); SFNP DI commission | H10: No (not verified) | I10: No | J10: No | K10: Not verified | L10: Partial — AS-experienced neuropaediatrics | M10: Affiliation/activity currency to verify. Sources: https://www.livret-angelman-afsa.org/les-contributeurs; https://www.angelman-afsa.org/afsa/son-equipe/conseil-medical-et-scientifique/nouvelle-presidence-du-cms
A11: France | B11: 3 | C11: Toulon | D11: Centre Hospitalier Intercommunal Toulon–La Seyne | E11: Génétique médicale (CLAD Sud-Est network site) | F11: Dr Florence Riccardi | G11: Current AFSA CMS member (geneticist) | H11: No | I11: No | J11: No | K11: No (CLAD Sud-Est network site via Lyon) | L11: Partial | M11: Non-university hospital; included because of named AS-engaged geneticist. Sources: https://www.angelman-afsa.org/afsa/son-equipe/conseil-medical-et-scientifique/afsa/son-equipe/conseil-medical-et-scientifique/le-conseil-medical-et-scientifique; https://ern-ithaca.eu/about-us/expert-centers/ern-ithaca-lyon-center/
A12: France | B12: 3 | C12: Paris | D12: GHU Paris Psychiatrie & Neurosciences (Sainte-Anne) | E12: Psychiatrie | F12: Dr Boris Chaumette | G12: Current AFSA CMS member (psychiatrist — behavioural/psychiatric AS phenotype) | H12: No | I12: No | J12: No | K12: No | L12: Partial — psychiatry of genetic NDD | M12: Behaviour/psychiatry voice for advisory boards. Sources: https://www.angelman-afsa.org/afsa/son-equipe/conseil-medical-et-scientifique/afsa/son-equipe/conseil-medical-et-scientifique/le-conseil-medical-et-scientifique
A13: France | B13: 3 | C13: Aix-en-Provence | D13: Centre Hospitalier du Pays d'Aix | E13: Neuropédiatrie | F13: Dr Marie-Odile Livet | G13: Historic AFSA CMS member; co-author of foundational French AS genotype-phenotype series (Moncla et al. 1999) | H13: No | I13: No (historic only) | J13: No | K13: No | L13: Partial | M13: Likely retired/inactive — verify before outreach. Sources: https://www.livret-angelman-afsa.org/les-contributeurs; https://www.has-sante.fr/upload/docs/application/pdf/2021-11/argumentaire_pnds_angelman_vf.pdf
A14: France | B14: 3 | C14: Lille | D14: CHU de Lille | E14: Clinique de génétique Guy Fontaine | F14: Not publicly identified — verify locally | G14: University genetics service active in national NDD genomics (episignature consortium) | H14: No | I14: No AS-specific | J14: No | K14: Not verified | L14: Partial | M14: Sources: https://pubmed.ncbi.nlm.nih.gov/37872275/
... A97: United Kingdom | B97: 3 | C97: Southampton | D97: University Hospital Southampton NHS FT — Princess Anne Hospital | E97: Wessex Clinical Genetics Service (and Wessex congenital anomaly registry linkage via EUROCAT/EUROlinkCAT) | F97: Dr Diana Gay Wellesley (Consultant Clinical Geneticist); Prof Joan K Morris (City St George's, University of London — epidemiology collaborator, last author) | G97: UK co-author of 2025 European population-based AS/PWS health-outcomes study (EUROlinkCAT) | H97: No | I97: Yes — disease (Abate MV…Wellesley DG, Morris JK. Arch Dis Child 2025;110(11):899-904; doi:10.1136/archdischild-2025-328786; PMID 40484454) — epidemiology, single paper | J97: No (congenital-anomaly registry linkage, not an AS registry/trial site) | K97: N/A (post-Brexit) — national analogue: Wessex regional clinical genetics service | L97: Partial (regional clinical genetics) | M97: Tier 3: tertiary capable; RWE/epidemiology value (registry-linked healthcare-utilisation data for AS) rather than trial readiness. Sources: https://adc.bmj.com/content/110/11/899; https://pure.ulster.ac.uk/ws/portalfiles/portal/221906804/Prader-Willi_Angelman_syndrome_-_accepted_version.pdf

Sheet KOL_Roster
A1: KOL_Roster — named Angelman syndrome KOLs, EU4+UK (scored per template §3; Tier 1 = 24–30, Tier 2 = 12–23, Tier 3 = 0–11)
A2: Country | B2: KOL | C2: Primary affiliation | D2: Role/Signal | E2: P1 guideline author | F2: P3 registry role | G2: Key publications/datasets (P2) | H2: Presentation at international conferences | I2: Engagement priority | J2: KOL Tier for TOV | K2: Score — Guideline authorship | L2: Score — Publications | M2: Score — Clinical trials | N2: Score — Academic appointment | O2: Score — Society roles | P2: Score — Speaker engagement | Q2: Score — Awards | R2: Total score | S2: Sources
A3: France | B3: Dr Delphine Héron | C3: AP-HP Pitié-Salpêtrière (Sorbonne Université), Génétique clinique; coordinator CRMR DI de causes rares (DéfiScience) | D3: PNDS Syndrome d'Angelman coordinator (2021); national CRMR DI coordinator; ITHACA Paris consortium; AFSA CMS member | E3: Yes — PNDS Angelman 2021 (coordinator) | F3: No (no FR REVEAL/Aspire site) | G3: PNDS + argumentaire Syndrome d'Angelman (HAS, Nov 2021). Peer-reviewed AS papers 2021–26 not verified in this pass. | H3: Not identified in this pass — verify (ASA/ASF/FAST congress programmes) | I3: TIER 2 — engage (national anchor; first-wave advisory-board lead despite score) | J3: =IF(R3>=24,1,IF(R3>=12,2,3)) -> 2 | K3: 3 | L3: 1 | M3: 1 | N3: 3 | O3: 3 | P3: 1 | Q3: 0 | R3: =SUM(K3:Q3) -> 12 | S3: https://www.has-sante.fr/upload/docs/application/pdf/2021-11/pnds_angelman_vf_.doc.pdf; https://www.has-sante.fr/upload/docs/application/pdf/2021-11/argumentaire_pnds_angelman_vf.pdf; https://ern-ithaca.eu/about-us/expert-centers/ern-ithaca-paris-center-robert-debre-university-hospital/; https://www.angelman-afsa.org/afsa/son-equipe/conseil-medical-et-scientifique/afsa/son-equipe/conseil-medical-et-scientifique/le-conseil-medical-et-scientifique
A4: France | B4: Pr Rima Nabbout | C4: AP-HP Necker-Enfants Malades / Institut Imagine — CRéER (rare epilepsies) | D4: EpiCARE HCP coordinator & founding steering member; chairs BNDMR scientific committee; PI of international/industry rare-epilepsy trials | E4: No (AS) | F4: BNDMR scientific-committee chair (national rare-disease database, not AS-specific); No (no FR REVEAL/Aspire site) | G4: Rare/developmental-epilepsy output (e.g., KCNT1, fenfluramine DEE reviews listed on Imagine profile); AS-specific papers not verified | H4: ILAE working groups — specific oral presentations to verify | I4: TIER 2 — high value — epilepsy/trial-readiness anchor (not AS-specific) | J4: =IF(R4>=24,1,IF(R4>=12,2,3)) -> 2 | K4: 1 | L4: 5 | M4: 5 | N4: 5 | O4: 5 | P4: 1 | Q4: 0 | R4: =SUM(K4:Q4) -> 22 | S4: https://www.institutimagine.org/en/users/rimanabboutaphpfr; https://epi-care.eu/hospitals/necker-enfants-malades-aphp/; https://maladiesrares-necker.aphp.fr/rare-epilepsies/
A5: France | B5: Dr Nadia Bahi-Buisson | C5: AP-HP Necker-Enfants Malades — Neurologie pédiatrique | D5: Coordinating investigator in France for obudanersen HALOS (ION582-CS1, Necker); coordinating investigator for GTX-102 Ph2 basket (GTX-102-CL210); ERN ITHACA Paris consortium (DéfiScience axis) | E5: No | F5: Site — ION582 HALOS (FR coordinating investigator); Site — competitor (GTX-102 CL210 coordinator; CL302 LTE recruiting at Necker) | G5: Investigator/PI roles: HALOS NCT05127226 (ION582-CS1, FR coordinating investigator); GTX-102-CL210 Ph2 basket (FR coordinating investigator). AS peer-reviewed papers not verified (PubMed check pending). | H5: Not identified in this pass — verify (ASA/ASF/FAST congress programmes) | I5: TIER 2 — must-engage (ION582-specific) — HALOS investigator; also competitor-trial PI | J5: =IF(R5>=24,1,IF(R5>=12,2,3)) -> 2 | K5: 1 | L5: 1 | M5: 5 | N5: 3 | O5: 1 | P5: 1 | Q5: 0 | R5: =SUM(K5:Q5) -> 12 | S5: https://www.aphp.fr/registre-des-essais-cliniques/etude-visant-evaluer-la-securite-la-tolerance-la-pharmacocinetique-et; https://www.aphp.fr/registre-des-essais-cliniques/etude-en-ouvert-de-phase-2-de-type-panier-visant-evaluer-linnocuite; https://ern-ithaca.eu/about-us/expert-centers/ern-ithaca-paris-center-robert-debre-university-hospital/
A6: France | B6: Pr Alain Verloes | C6: AP-HP Robert-Debré — Head, Clinical Genetics Department; CLAD-IDF coordinator | D6: ERN ITHACA EU coordinator (since 2018) | E6: No (AS) | F6: No (no FR REVEAL/Aspire site) | G6: AS-specific output not verified (verify PubMed) | H6: ERN ITHACA/ESHG meetings — verify specific talks | I6: TIER 2 — engage (ERN network gateway) | J6: =IF(R6>=24,1,IF(R6>=12,2,3)) -> 2 | K6: 1 | L6: 1 | M6: 1 | N6: 5 | O6: 5 | P6: 1 | Q6: 0 | R6: =SUM(K6:Q6) -> 14 | S6: https://ern-ithaca.eu/about-us/who-we-are/; https://ern-ithaca.eu/about-us/expert-centers/ern-ithaca-paris-center-robert-debre-university-hospital/; https://robertdebre.aphp.fr/centre-de-reference-des-anomalies-du-developpement-syndromes-malformatif-dile-de-france
A7: France | B7: Pr Mathieu Milh | C7: AP-HM La Timone Enfants — Neurologie pédiatrique | D7: Heads national reference centres for rare epilepsies (CRéER coordinator) and rare severe developmental disorders; national coordinating investigator, GTX-102 LTE (GTX-102-CL302) | E7: No | F7: Coordinator (national) — competitor GTX-102 LTE CL302; Timone GTX-102 Ph1/2 site | G7: STXBP1 French cohort phenotyping (per ESCO profile); AS-specific output not verified; GTX-102-CL302 LTE national coordinating investigator | H7: Not identified in this pass — verify (ASA/ASF/FAST congress programmes) | I7: TIER 2 — high value — competitor-trial PI (displaceable after Aspire failure) | J7: =IF(R7>=24,1,IF(R7>=12,2,3)) -> 2 | K7: 1 | L7: 1 | M7: 3 | N7: 5 | O7: 3 | P7: 1 | Q7: 0 | R7: =SUM(K7:Q7) -> 14 | S7: https://stxbp1eu.org/france/; https://kcnq2francedeveloppement.fr/pole-recherche/; https://maladiesrares-necker.aphp.fr/rare-epilepsies/; https://hopital-broca.aphp.fr/registre-des-essais-cliniques/etude-dextension-long-terme-portant-sur-la-securite-demploi-et-65; https://clinicaltrials.gov/study/NCT04259281
A8: France | B8: Pr Laurence Faivre | C8: CHU Dijon Bourgogne — Centre de Génétique; FHU TRANSLAD | D8: ERN ITHACA Dijon lead | E8: No | F8: No (no FR REVEAL/Aspire site) | G8: NDD episignature co-author EJHG 2024 (PMID 37872275); AS-specific not verified | H8: Not identified in this pass — verify (ASA/ASF/FAST congress programmes) | I8: TIER 2 — engage (genomic-medicine/RWE partner) | J8: =IF(R8>=24,1,IF(R8>=12,2,3)) -> 2 | K8: 1 | L8: 1 | M8: 1 | N8: 5 | O8: 3 | P8: 1 | Q8: 0 | R8: =SUM(K8:Q8) -> 12 | S8: https://ern-ithaca.eu/about-us/expert-centers/ern-ithaca-dijon-center/; https://pubmed.ncbi.nlm.nih.gov/37872275/
A9: France | B9: Dr Perrine Charles | C9: AP-HP Pitié-Salpêtrière — Neurologie / CRMR DI de causes rares | D9: AFSA CMS neurologist; adult AS follow-up (AFSA adult-transition training 2021) | E9: No (individual PNDS role not verified) | F9: No (no FR REVEAL/Aspire site) | G9: Co-author, NDD episignature evaluation, Eur J Hum Genet 2024;32:190-199 (PMID 37872275; not AS-specific) | H9: Not identified in this pass — verify (ASA/ASF/FAST congress programmes) | I9: TIER 3 — monitor (adult-AS voice; REVEAL adult-cohort relevance) | J9: =IF(R9>=24,1,IF(R9>=12,2,3)) -> 3 | K9: 1 | L9: 1 | M9: 1 | N9: 1 | O9: 3 | P9: 1 | Q9: 0 | R9: =SUM(K9:Q9) -> 8 | S9: https://www.angelman-afsa.org/afsa/son-equipe/conseil-medical-et-scientifique/afsa/son-equipe/conseil-medical-et-scientifique/le-conseil-medical-et-scientifique; https://www.angelman-afsa.org/fichiers/Rapport%20d'Activites%202021-1654173306.pdf; https://pubmed.ncbi.nlm.nih.gov/37872275/
A10: France | B10: Pr Angèle Consoli | C10: AP-HP Pitié-Salpêtrière — Pédopsychiatrie | D10: AFSA CMS child psychiatrist; AFSA family-handbook author | E10: No (not verified) | F10: No (no FR REVEAL/Aspire site) | G10: AFSA livret contributor (behaviour); AS peer-reviewed output not verified | H10: Not identified in this pass — verify (ASA/ASF/FAST congress programmes) | I10: TIER 3 — monitor (behaviour endpoints voice) | J10: =IF(R10>=24,1,IF(R10>=12,2,3)) -> 3 | K10: 1 | L10: 1 | M10: 1 | N10: 3 | O10: 3 | P10: 1 | Q10: 0 | R10: =SUM(K10:Q10) -> 10 | S10: https://www.angelman-afsa.org/afsa/son-equipe/conseil-medical-et-scientifique/afsa/son-equipe/conseil-medical-et-scientifique/le-conseil-medical-et-scientifique; https://www.livret-angelman-afsa.org/les-contributeurs
A11: France | B11: Dr Marie Hully | C11: AP-HP Necker-Enfants Malades — Neuropédiatrie (CRMR DI & polyhandicap) and Rééducation pédiatrique | D11: Former AFSA CMS president (succeeded Peudenier); head SFNP Commission Handicaps et Déficiences Intellectuelles | E11: Contributor via AFSA CMS (CMS finalised PNDS 2021) — individual authorship unverified | F11: No (no FR REVEAL/Aspire site) | G11: AS peer-reviewed output not verified | H11: Not identified in this pass — verify (ASA/ASF/FAST congress programmes) | I11: TIER 3 — monitor; upgrade candidate (AS clinic lead at Necker — verify) | J11: =IF(R11>=24,1,IF(R11>=12,2,3)) -> 3 | K11: 1 | L11: 1 | M11: 1 | N11: 3 | O11: 3 | P11: 1 | Q11: 0 | R11: =SUM(K11:Q11) -> 10 | S11: https://www.angelman-afsa.org/afsa/son-equipe/conseil-medical-et-scientifique/nouvelle-presidence-du-cms; https://www.angelman-afsa.org/afsa/son-equipe/conseil-medical-et-scientifique/afsa/son-equipe/conseil-medical-et-scientifique/le-conseil-medical-et-scientifique; https://www.angelman-afsa.org/fichiers/Rapport%20d'Activites%202021-1654173306.pdf
A12: France | B12: Dr Marlène Rio | C12: AP-HP Necker-Enfants Malades — Génétique | D12: ERN ITHACA Paris consortium member (DéfiScience axis) | E12: No | F12: No (no FR REVEAL/Aspire site) | G12: AS-specific output not verified | H12: Not identified in this pass — verify (ASA/ASF/FAST congress programmes) | I12: TIER 3 — monitor | J12: =IF(R12>=24,1,IF(R12>=12,2,3)) -> 3 | K12: 1 | L12: 1 | M12: 1 | N12: 1 | O12: 1 | P12: 1 | Q12: 0 | R12: =SUM(K12:Q12) -> 6 | S12: https://ern-ithaca.eu/about-us/expert-centers/ern-ithaca-paris-center-robert-debre-university-hospital/
A13: France | B13: Dr David Germanaud | C13: AP-HP Robert-Debré — Génétique | D13: ERN ITHACA Paris consortium member (DéfiScience axis) | E13: No | F13: No (no FR REVEAL/Aspire site) | G13: AS-specific output not verified | H13: Not identified in this pass — verify (ASA/ASF/FAST congress programmes) | I13: TIER 3 — monitor | J13: =IF(R13>=24,1,IF(R13>=12,2,3)) -> 3 | K13: 1 | L13: 1 | M13: 1 | N13: 1 | O13: 1 | P13: 1 | Q13: 0 | R13: =SUM(K13:Q13) -> 6 | S13: https://ern-ithaca.eu/about-us/expert-centers/ern-ithaca-paris-center-robert-debre-university-hospital/
A14: France | B14: Dr Béatrice Desnous | C14: AP-HM La Timone Enfants — Neurologie pédiatrique (CRéER / CRMR DI) | D14: Current AFSA CMS president; MD-PhD child neurologist/neurophysiologist | E14: No (not verified) | F14: No (no FR REVEAL/Aspire site) | G14: Genetic NDD/STXBP1 clinical studies; AS-specific output not verified | H14: Not identified in this pass — verify (ASA/ASF/FAST congress programmes) | I14: TIER 3 — monitor; high community value (AFSA CMS president) | J14: =IF(R14>=24,1,IF(R14>=12,2,3)) -> 3 | K14: 1 | L14: 1 | M14: 1 | N14: 3 | O14: 3 | P14: 1 | Q14: 0 | R14: =SUM(K14:Q14) -> 10 | S14: https://www.angelman-afsa.org/afsa/son-equipe/conseil-medical-et-scientifique/afsa/son-equipe/conseil-medical-et-scientifique/le-conseil-medical-et-scientifique; https://stxbp1eu.org/france/; https://kcnq2francedeveloppement.fr/pole-recherche/
... A99: United Kingdom | B99: Hayley Denyer | C99: UCL Great Ormond Street Institute of Child Health (per 2019 affiliation — verify) | D99: [Non-physician — psychologist/researcher] Researcher; AS sleep co-author | E99: No | F99: No | G99: Co-author Front Psychiatry 2019;10:874 | H99: Not verified | I99: TIER 3 — monitor — verify current affiliation (GOSH link) | J99: =IF(R99>=24,1,IF(R99>=12,2,3)) -> 3 | K99: 1 | L99: 1 | M99: 1 | N99: 1 | O99: 1 | P99: 1 | Q99: 0 | R99: =SUM(K99:Q99) -> 6 | S99: https://doaj.org/article/6fdb3ab1e55c4c2f9932c00ad98c1c89

Sheet Tier_Counts
A1: Tier_Counts — centres and KOLs by country × tier (all counts are live COUNTIFS on Country_Centres / KOL_Roster)
A3: A. CENTRES × COUNTRY × TIER
A4: Country | B4: Tier 1 | C4: Tier 2 | D4: Tier 3 | E4: Tier 4 | F4: Total enumerated | G4: Notes
A5: France | B5: =COUNTIFS(Country_Centres!$A$3:$A$97,$A5,Country_Centres!$B$3:$B$97,1) -> 3 | C5: =COUNTIFS(Country_Centres!$A$3:$A$97,$A5,Country_Centres!$B$3:$B$97,2) -> 4 | D5: =COUNTIFS(Country_Centres!$A$3:$A$97,$A5,Country_Centres!$B$3:$B$97,3) -> 10 | E5: =COUNTIFS(Country_Centres!$A$3:$A$97,$A5,Country_Centres!$B$3:$B$97,4) -> 0 | F5: =COUNTIF(Country_Centres!$A$3:$A$97,$A5) -> 17 | G5: Tier 4: not enumerated — not requested. France's national P1 anchor is Pitié-Salpêtrière (PNDS 2021). Its trial anchors are Necker (ION582 HALOS coordinating centre, plus GTX-102) and Timone (GTX-102 Ph1/2 and LTE coordination). Neither hosts REVEAL. KOL scores stay low pending a verified PubMed sweep.
A6: Germany | B6: =COUNTIFS(Country_Centres!$A$3:$A$97,$A6,Country_Centres!$B$3:$B$97,1) -> 3 | C6: =COUNTIFS(Country_Centres!$A$3:$A$97,$A6,Country_Centres!$B$3:$B$97,2) -> 4 | D6: =COUNTIFS(Country_Centres!$A$3:$A$97,$A6,Country_Centres!$B$3:$B$97,3) -> 10 | E6: =COUNTIFS(Country_Centres!$A$3:$A$97,$A6,Country_Centres!$B$3:$B$97,4) -> 0 | F6: =COUNTIF(Country_Centres!$A$3:$A$97,$A6) -> 17 | G6: Tier 4: not enumerated — not requested. Germany's AS care is concentrated in three Angelman e.V./ASF-recognised centres: Munich (paediatric; first EU REVEAL site), Leipzig (paediatric + national AS registry) and Aachen (adults). Diagnostic leadership sits in Essen (EMQN/ACGS and AWMF guideline authors). Tier 1 rests partly on national-analogue pillars because no German clinician authored the 2022 international consensus and none of the three AS centres is an ERN ITHACA HCP. ERN ITHACA/EpiCARE HCPs without AS activity are placed in Tiers 2–3.
A7: Italy | B7: =COUNTIFS(Country_Centres!$A$3:$A$97,$A7,Country_Centres!$B$3:$B$97,1) -> 1 | C7: =COUNTIFS(Country_Centres!$A$3:$A$97,$A7,Country_Centres!$B$3:$B$97,2) -> 11 | D7: =COUNTIFS(Country_Centres!$A$3:$A$97,$A7,Country_Centres!$B$3:$B$97,3) -> 16 | E7: =COUNTIFS(Country_Centres!$A$3:$A$97,$A7,Country_Centres!$B$3:$B$97,4) -> 0 | F7: =COUNTIF(Country_Centres!$A$3:$A$97,$A7) -> 28 | G7: Tier 4: not enumerated — not requested. Italy has no national AS guideline, but it has one national patient-reported registry (RISA, FROM Bergamo; 82 pts; PMID 38930051). Because no centre qualifies on P1, Tier 1 rests on P3 national-cohort coordination: only Besta qualifies, as the FAST Italia AS Biobank lead plus REVEAL/Aurora site. Obudanersen's real Italian evidence base is the REVEAL/HALOS cluster at Besta, Pisa (Stella Maris/AOU Pisana), OPBG and Medea Conegliano. Competitor Aurora sites (Meyer, Gemelli, Besta) are in the same tier. A long tail of OR.S.A.-listed child-neuropsychiatry/epilepsy services and ERN ITHACA/EpiCARE HCPs makes up Tier 2–3.
A8: Spain | B8: =COUNTIFS(Country_Centres!$A$3:$A$97,$A8,Country_Centres!$B$3:$B$97,1) -> 0 | C8: =COUNTIFS(Country_Centres!$A$3:$A$97,$A8,Country_Centres!$B$3:$B$97,2) -> 5 | D8: =COUNTIFS(Country_Centres!$A$3:$A$97,$A8,Country_Centres!$B$3:$B$97,3) -> 12 | E8: =COUNTIFS(Country_Centres!$A$3:$A$97,$A8,Country_Centres!$B$3:$B$97,4) -> 0 | F8: =COUNTIF(Country_Centres!$A$3:$A$97,$A8) -> 17 | G8: Tier 4: not enumerated — not requested. Spain has two monographic AS units — Parc Taulí (Sabadell; ASF clinic; first Spanish REVEAL site) and Puerta de Hierro (Majadahonda; national AS natural-history coordinator) — plus SJD Barcelona (REVEAL site; ERN ITHACA+EpiCARE coordinator). No centre meets strict Tier 1 because there is no Spanish P1 guideline author and the two AS units are not ERN ITHACA/EpiCARE members; treat Parc Taulí and Puerta de Hierro as Tier-1-equivalent national anchors. Care is concentrated (chronic disease) — Tier 3 ERN/university hospitals matter mainly for referral and future IT-ASO capacity.
A9: United Kingdom | B9: =COUNTIFS(Country_Centres!$A$3:$A$97,$A9,Country_Centres!$B$3:$B$97,1) -> 1 | C9: =COUNTIFS(Country_Centres!$A$3:$A$97,$A9,Country_Centres!$B$3:$B$97,2) -> 4 | D9: =COUNTIFS(Country_Centres!$A$3:$A$97,$A9,Country_Centres!$B$3:$B$97,3) -> 11 | E9: =COUNTIFS(Country_Centres!$A$3:$A$97,$A9,Country_Centres!$B$3:$B$97,4) -> 0 | F9: =COUNTIF(Country_Centres!$A$3:$A$97,$A9) -> 16 | G9: Tier 4: not enumerated — not requested. After follow-up verification UK has one Tier 1 anchor — Oxford (ION582 HALOS+REVEAL site, ex-GTX-102 site, national natural-history coordinator) — with Manchester (UK's only specialist AS clinic, 2009 guideline lead, AS register) provisionally Tier 2 pending confirmation of 2021–2026 publications, alongside GOSH (REVEAL site), Cambridge (ex-GTX-102 site) and the Birmingham behaviour/sleep hub. P4 = N/A (post-Brexit); tiering uses national leadership, registry and trial signal. No UK KOL reaches Tier 1 by score.
A10: TOTAL (EU4+UK) | B10: =SUM(B5:B9) -> 8 | C10: =SUM(C5:C9) -> 28 | D10: =SUM(D5:D9) -> 59 | E10: =SUM(E5:E9) -> 0 | F10: =SUM(F5:F9) -> 95 | G10: ="Tier 4 not enumerated — not requested. Reconciles with Country_Centres row count: "&IF(F10=COUNTA(Country_Centres!$D$3:$D$97),"YES","NO — check") -> Tier 4 not enumerated — not requested. Reconciles with Country_Centres row count: YES
A12: B. KOLs × COUNTRY × TIER (KOL Tier for TOV, formula-driven from Total score)
A13: Country | B13: Tier 1 | C13: Tier 2 | D13: Tier 3 | E13: Total enumerated | F13: Notes
A14: France | B14: =COUNTIFS(KOL_Roster!$A$3:$A$99,$A14,KOL_Roster!$J$3:$J$99,1) -> 0 | C14: =COUNTIFS(KOL_Roster!$A$3:$A$99,$A14,KOL_Roster!$J$3:$J$99,2) -> 6 | D14: =COUNTIFS(KOL_Roster!$A$3:$A$99,$A14,KOL_Roster!$J$3:$J$99,3) -> 13 | E14: =COUNTIF(KOL_Roster!$A$3:$A$99,$A14) -> 19 | F14: 19 named KOLs (minimum 15 per country met). Highest total score 22/30 (Pr Rima Nabbout). No KOL reaches Tier 1 (24–30): publication/speaker scores use the evidence floor because live PubMed access was unavailable — re-score after a PubMed author sweep.
A15: Germany | B15: =COUNTIFS(KOL_Roster!$A$3:$A$99,$A15,KOL_Roster!$J$3:$J$99,1) -> 0 | C15: =COUNTIFS(KOL_Roster!$A$3:$A$99,$A15,KOL_Roster!$J$3:$J$99,2) -> 8 | D15: =COUNTIFS(KOL_Roster!$A$3:$A$99,$A15,KOL_Roster!$J$3:$J$99,3) -> 12 | E15: =COUNTIF(KOL_Roster!$A$3:$A$99,$A15) -> 20 | F15: 20 named KOLs (minimum 15 per country met). Highest total score 14/30 (Dr. rer. nat. Jasmin Beygo). No KOL reaches Tier 1 (24–30): publication/speaker scores use the evidence floor because live PubMed access was unavailable — re-score after a PubMed author sweep.
A16: Italy | B16: =COUNTIFS(KOL_Roster!$A$3:$A$99,$A16,KOL_Roster!$J$3:$J$99,1) -> 0 | C16: =COUNTIFS(KOL_Roster!$A$3:$A$99,$A16,KOL_Roster!$J$3:$J$99,2) -> 8 | D16: =COUNTIFS(KOL_Roster!$A$3:$A$99,$A16,KOL_Roster!$J$3:$J$99,3) -> 15 | E16: =COUNTIF(KOL_Roster!$A$3:$A$99,$A16) -> 23 | F16: 23 named KOLs (minimum 15 per country met). Highest total score 18/30 (Prof.ssa Roberta Battini). No KOL reaches Tier 1 (24–30): publication/speaker scores use the evidence floor because live PubMed access was unavailable — re-score after a PubMed author sweep.
A17: Spain | B17: =COUNTIFS(KOL_Roster!$A$3:$A$99,$A17,KOL_Roster!$J$3:$J$99,1) -> 0 | C17: =COUNTIFS(KOL_Roster!$A$3:$A$99,$A17,KOL_Roster!$J$3:$J$99,2) -> 6 | D17: =COUNTIFS(KOL_Roster!$A$3:$A$99,$A17,KOL_Roster!$J$3:$J$99,3) -> 12 | E17: =COUNTIF(KOL_Roster!$A$3:$A$99,$A17) -> 18 | F17: 18 named KOLs (minimum 15 per country met). Highest total score 20/30 (Dra. Ana Roche Martínez (MD, PhD; neuropaediatrician)). No KOL reaches Tier 1 (24–30): publication/speaker scores use the evidence floor because live PubMed access was unavailable — re-score after a PubMed author sweep.
A18: United Kingdom | B18: =COUNTIFS(KOL_Roster!$A$3:$A$99,$A18,KOL_Roster!$J$3:$J$99,1) -> 0 | C18: =COUNTIFS(KOL_Roster!$A$3:$A$99,$A18,KOL_Roster!$J$3:$J$99,2) -> 5 | D18: =COUNTIFS(KOL_Roster!$A$3:$A$99,$A18,KOL_Roster!$J$3:$J$99,3) -> 12 | E18: =COUNTIF(KOL_Roster!$A$3:$A$99,$A18) -> 17 | F18: 17 named KOLs (minimum 15 per country met). Highest total score 22/30 (Prof Jill Clayton-Smith). No KOL reaches Tier 1 (24–30): publication/speaker scores use the evidence floor because live PubMed access was unavailable — re-score after a PubMed author sweep. Only 8 of 17 named KOLs are physicians (see Verification_Flags).
A19: TOTAL (EU4+UK) | B19: =SUM(B14:B18) -> 0 | C19: =SUM(C14:C18) -> 33 | D19: =SUM(D14:D18) -> 64 | E19: =SUM(E14:E18) -> 97 | F19: ="Reconciles with KOL_Roster row count: "&IF(E19=COUNTA(KOL_Roster!$B$3:$B$99),"YES","NO — check") -> Reconciles with KOL_Roster row count: YES
A21: C. CROSS-CUTS — CENTRES (COUNTIF/COUNTIFS with wildcards on Country_Centres P-columns)
A22: Cross-cut (criterion) | B22: France | C22: Germany | D22: Italy | E22: Spain | F22: United Kingdom | G22: TOTAL (EU4+UK)
A23: Centres hosting a P1 guideline author (P1 starts "Yes") | B23: =COUNTIFS(Country_Centres!$A$3:$A$97,B$22,Country_Centres!$H$3:$H$97,"Yes*") -> 1 | C23: =COUNTIFS(Country_Centres!$A$3:$A$97,C$22,Country_Centres!$H$3:$H$97,"Yes*") -> 4 | D23: =COUNTIFS(Country_Centres!$A$3:$A$97,D$22,Country_Centres!$H$3:$H$97,"Yes*") -> 0 | E23: =COUNTIFS(Country_Centres!$A$3:$A$97,E$22,Country_Centres!$H$3:$H$97,"Yes*") -> 0 | F23: =COUNTIFS(Country_Centres!$A$3:$A$97,F$22,Country_Centres!$H$3:$H$97,"Yes*") -> 1 | G23: =SUM(B23:F23) -> 6
A24: Centres with P2 publication / trial authorship (P2 starts "Yes") | B24: =COUNTIFS(Country_Centres!$A$3:$A$97,B$22,Country_Centres!$I$3:$I$97,"Yes*") -> 3 | C24: =COUNTIFS(Country_Centres!$A$3:$A$97,C$22,Country_Centres!$I$3:$I$97,"Yes*") -> 4 | D24: =COUNTIFS(Country_Centres!$A$3:$A$97,D$22,Country_Centres!$I$3:$I$97,"Yes*") -> 7 | E24: =COUNTIFS(Country_Centres!$A$3:$A$97,E$22,Country_Centres!$I$3:$I$97,"Yes*") -> 5 | F24: =COUNTIFS(Country_Centres!$A$3:$A$97,F$22,Country_Centres!$I$3:$I$97,"Yes*") -> 6 | G24: =SUM(B24:F24) -> 25
A25: …of which with ION582 (obudanersen) trial signal (P2 "Yes" and contains "ION582") | B25: =COUNTIFS(Country_Centres!$A$3:$A$97,B$22,Country_Centres!$I$3:$I$97,"Yes*",Country_Centres!$I$3:$I$97,"*ION582*") -> 1 | C25: =COUNTIFS(Country_Centres!$A$3:$A$97,C$22,Country_Centres!$I$3:$I$97,"Yes*",Country_Centres!$I$3:$I$97,"*ION582*") -> 1 | D25: =COUNTIFS(Country_Centres!$A$3:$A$97,D$22,Country_Centres!$I$3:$I$97,"Yes*",Country_Centres!$I$3:$I$97,"*ION582*") -> 4 | E25: =COUNTIFS(Country_Centres!$A$3:$A$97,E$22,Country_Centres!$I$3:$I$97,"Yes*",Country_Centres!$I$3:$I$97,"*ION582*") -> 2 | F25: =COUNTIFS(Country_Centres!$A$3:$A$97,F$22,Country_Centres!$I$3:$I$97,"Yes*",Country_Centres!$I$3:$I$97,"*ION582*") -> 2 | G25: =SUM(B25:F25) -> 10
A26: …of which with competitor-trial signal (P2 "Yes" and contains competitor / apazunersen / GTX-102 / rugonersen / Aspire) | B26: {=SUMPRODUCT((Country_Centres!$A$3:$A$97=B$22)*(LEFT(Country_Centres!$I$3:$I$97,3)="Yes")*((ISNUMBER(SEARCH("competitor",Country_Centres!$I$3:$I$97))+ISNUMBER(SEARCH("apazunersen",Country_Centres!$I$3:$I$97))+ISNUMBER(SEARCH("GTX-102",Country_Centres!$I$3:$I$97))+ISNUMBER(SEARCH("rugonersen",Country_Centres!$I$3:$I$97))+ISNUMBER(SEARCH("Aspire",Country_Centres!$I$3:$I$97)))>0))} -> 2 | C26: {=SUMPRODUCT((Country_Centres!$A$3:$A$97=C$22)*(LEFT(Country_Centres!$I$3:$I$97,3)="Yes")*((ISNUMBER(SEARCH("competitor",Country_Centres!$I$3:$I$97))+ISNUMBER(SEARCH("apazunersen",Country_Centres!$I$3:$I$97))+ISNUMBER(SEARCH("GTX-102",Country_Centres!$I$3:$I$97))+ISNUMBER(SEARCH("rugonersen",Country_Centres!$I$3:$I$97))+ISNUMBER(SEARCH("Aspire",Country_Centres!$I$3:$I$97)))>0))} -> 3 | D26: {=SUMPRODUCT((Country_Centres!$A$3:$A$97=D$22)*(LEFT(Country_Centres!$I$3:$I$97,3)="Yes")*((ISNUMBER(SEARCH("competitor",Country_Centres!$I$3:$I$97))+ISNUMBER(SEARCH("apazunersen",Country_Centres!$I$3:$I$97))+ISNUMBER(SEARCH("GTX-102",Country_Centres!$I$3:$I$97))+ISNUMBER(SEARCH("rugonersen",Country_Centres!$I$3:$I$97))+ISNUMBER(SEARCH("Aspire",Country_Centres!$I$3:$I$97)))>0))} -> 3 | E26: {=SUMPRODUCT((Country_Centres!$A$3:$A$97=E$22)*(LEFT(Country_Centres!$I$3:$I$97,3)="Yes")*((ISNUMBER(SEARCH("competitor",Country_Centres!$I$3:$I$97))+ISNUMBER(SEARCH("apazunersen",Country_Centres!$I$3:$I$97))+ISNUMBER(SEARCH("GTX-102",Country_Centres!$I$3:$I$97))+ISNUMBER(SEARCH("rugonersen",Country_Centres!$I$3:$I$97))+ISNUMBER(SEARCH("Aspire",Country_Centres!$I$3:$I$97)))>0))} -> 5 | F26: {=SUMPRODUCT((Country_Centres!$A$3:$A$97=F$22)*(LEFT(Country_Centres!$I$3:$I$97,3)="Yes")*((ISNUMBER(SEARCH("competitor",Country_Centres!$I$3:$I$97))+ISNUMBER(SEARCH("apazunersen",Country_Centres!$I$3:$I$97))+ISNUMBER(SEARCH("GTX-102",Country_Centres!$I$3:$I$97))+ISNUMBER(SEARCH("rugonersen",Country_Centres!$I$3:$I$97))+ISNUMBER(SEARCH("Aspire",Country_Centres!$I$3:$I$97)))>0))} -> 3 | G26: =SUM(B26:F26) -> 16
A27: Centres with a P3 coordinator role (P3 contains "Coordinator") | B27: =COUNTIFS(Country_Centres!$A$3:$A$97,B$22,Country_Centres!$J$3:$J$97,"*Coordinator*") -> 1 | C27: =COUNTIFS(Country_Centres!$A$3:$A$97,C$22,Country_Centres!$J$3:$J$97,"*Coordinator*") -> 1 | D27: =COUNTIFS(Country_Centres!$A$3:$A$97,D$22,Country_Centres!$J$3:$J$97,"*Coordinator*") -> 2 | E27: =COUNTIFS(Country_Centres!$A$3:$A$97,E$22,Country_Centres!$J$3:$J$97,"*Coordinator*") -> 1 | F27: =COUNTIFS(Country_Centres!$A$3:$A$97,F$22,Country_Centres!$J$3:$J$97,"*Coordinator*") -> 2 | G27: =SUM(B27:F27) -> 7
A28: Centres listed as P3 sites (P3 contains "Site", excluding "No…" entries) | B28: =COUNTIFS(Country_Centres!$A$3:$A$97,B$22,Country_Centres!$J$3:$J$97,"*Site*",Country_Centres!$J$3:$J$97,"<>No*") -> 2 | C28: =COUNTIFS(Country_Centres!$A$3:$A$97,C$22,Country_Centres!$J$3:$J$97,"*Site*",Country_Centres!$J$3:$J$97,"<>No*") -> 3 | D28: =COUNTIFS(Country_Centres!$A$3:$A$97,D$22,Country_Centres!$J$3:$J$97,"*Site*",Country_Centres!$J$3:$J$97,"<>No*") -> 6 | E28: =COUNTIFS(Country_Centres!$A$3:$A$97,E$22,Country_Centres!$J$3:$J$97,"*Site*",Country_Centres!$J$3:$J$97,"<>No*") -> 5 | F28: =COUNTIFS(Country_Centres!$A$3:$A$97,F$22,Country_Centres!$J$3:$J$97,"*Site*",Country_Centres!$J$3:$J$97,"<>No*") -> 4 | G28: =SUM(B28:F28) -> 20
A29: Centres that are P4 ERN ITHACA / EpiCARE HCPs (P4 starts "Yes") | B29: =COUNTIFS(Country_Centres!$A$3:$A$97,B$22,Country_Centres!$K$3:$K$97,"Yes*") -> 6 | C29: =COUNTIFS(Country_Centres!$A$3:$A$97,C$22,Country_Centres!$K$3:$K$97,"Yes*") -> 12 | D29: =COUNTIFS(Country_Centres!$A$3:$A$97,D$22,Country_Centres!$K$3:$K$97,"Yes*") -> 16 | E29: =COUNTIFS(Country_Centres!$A$3:$A$97,E$22,Country_Centres!$K$3:$K$97,"Yes*") -> 6 | F29: =COUNTIFS(Country_Centres!$A$3:$A$97,F$22,Country_Centres!$K$3:$K$97,"Yes*") -> 0 | G29: =SUM(B29:F29) -> 40
A30: Centres with an explicit P5 Angelman programme (P5 = "Yes*") | B30: =COUNTIFS(Country_Centres!$A$3:$A$97,B$22,Country_Centres!$L$3:$L$97,"Yes*") -> 3 | C30: =COUNTIFS(Country_Centres!$A$3:$A$97,C$22,Country_Centres!$L$3:$L$97,"Yes*") -> 3 | D30: =COUNTIFS(Country_Centres!$A$3:$A$97,D$22,Country_Centres!$L$3:$L$97,"Yes*") -> 18 | E30: =COUNTIFS(Country_Centres!$A$3:$A$97,E$22,Country_Centres!$L$3:$L$97,"Yes*") -> 2 | F30: =COUNTIFS(Country_Centres!$A$3:$A$97,F$22,Country_Centres!$L$3:$L$97,"Yes*") -> 1 | G30: =SUM(B30:F30) -> 27
A32: D. CROSS-CUTS — KOLs (COUNTIFS / SUMPRODUCT on KOL_Roster score and signal columns)
A33: Cross-cut (criterion) | B33: France | C33: Germany | D33: Italy | E33: Spain | F33: United Kingdom | G33: TOTAL (EU4+UK)
A34: KOLs with guideline publications (Guideline score ≥3 OR P1 column starts "Yes") | B34: {=SUMPRODUCT((KOL_Roster!$A$3:$A$99=B$33)*(((KOL_Roster!$K$3:$K$99>=3)+(LEFT(KOL_Roster!$E$3:$E$99,3)="Yes"))>0))} -> 1 | C34: {=SUMPRODUCT((KOL_Roster!$A$3:$A$99=C$33)*(((KOL_Roster!$K$3:$K$99>=3)+(LEFT(KOL_Roster!$E$3:$E$99,3)="Yes"))>0))} -> 3 | D34: {=SUMPRODUCT((KOL_Roster!$A$3:$A$99=D$33)*(((KOL_Roster!$K$3:$K$99>=3)+(LEFT(KOL_Roster!$E$3:$E$99,3)="Yes"))>0))} -> 0 | E34: {=SUMPRODUCT((KOL_Roster!$A$3:$A$99=E$33)*(((KOL_Roster!$K$3:$K$99>=3)+(LEFT(KOL_Roster!$E$3:$E$99,3)="Yes"))>0))} -> 1 | F34: {=SUMPRODUCT((KOL_Roster!$A$3:$A$99=F$33)*(((KOL_Roster!$K$3:$K$99>=3)+(LEFT(KOL_Roster!$E$3:$E$99,3)="Yes"))>0))} -> 1 | G34: =SUM(B34:F34) -> 6
A35: KOLs with clinical-trial roles (Clinical-trials score ≥3) | B35: =COUNTIFS(KOL_Roster!$A$3:$A$99,B$33,KOL_Roster!$M$3:$M$99,">=3") -> 3 | C35: =COUNTIFS(KOL_Roster!$A$3:$A$99,C$33,KOL_Roster!$M$3:$M$99,">=3") -> 2 | D35: =COUNTIFS(KOL_Roster!$A$3:$A$99,D$33,KOL_Roster!$M$3:$M$99,">=3") -> 6 | E35: =COUNTIFS(KOL_Roster!$A$3:$A$99,E$33,KOL_Roster!$M$3:$M$99,">=3") -> 4 | F35: =COUNTIFS(KOL_Roster!$A$3:$A$99,F$33,KOL_Roster!$M$3:$M$99,">=3") -> 2 | G35: =SUM(B35:F35) -> 17
A36: KOLs with disease publications (Publications score ≥3) | B36: =COUNTIFS(KOL_Roster!$A$3:$A$99,B$33,KOL_Roster!$L$3:$L$99,">=3") -> 1 | C36: =COUNTIFS(KOL_Roster!$A$3:$A$99,C$33,KOL_Roster!$L$3:$L$99,">=3") -> 2 | D36: =COUNTIFS(KOL_Roster!$A$3:$A$99,D$33,KOL_Roster!$L$3:$L$99,">=3") -> 7 | E36: =COUNTIFS(KOL_Roster!$A$3:$A$99,E$33,KOL_Roster!$L$3:$L$99,">=3") -> 7 | F36: =COUNTIFS(KOL_Roster!$A$3:$A$99,F$33,KOL_Roster!$L$3:$L$99,">=3") -> 8 | G36: =SUM(B36:F36) -> 25
A37: KOLs with an international presentation / meeting signal (column not blank, not "No…/None…/Not…", not "international … not verified") | B37: =COUNTIFS(KOL_Roster!$A$3:$A$99,B$33,KOL_Roster!$H$3:$H$99,"<>",KOL_Roster!$H$3:$H$99,"<>No*",KOL_Roster!$H$3:$H$99,"<>*international not verified*",KOL_Roster!$H$3:$H$99,"<>*international oral not verified*") -> 2 | C37: =COUNTIFS(KOL_Roster!$A$3:$A$99,C$33,KOL_Roster!$H$3:$H$99,"<>",KOL_Roster!$H$3:$H$99,"<>No*",KOL_Roster!$H$3:$H$99,"<>*international not verified*",KOL_Roster!$H$3:$H$99,"<>*international oral not verified*") -> 0 | D37: =COUNTIFS(KOL_Roster!$A$3:$A$99,D$33,KOL_Roster!$H$3:$H$99,"<>",KOL_Roster!$H$3:$H$99,"<>No*",KOL_Roster!$H$3:$H$99,"<>*international not verified*",KOL_Roster!$H$3:$H$99,"<>*international oral not verified*") -> 0 | E37: =COUNTIFS(KOL_Roster!$A$3:$A$99,E$33,KOL_Roster!$H$3:$H$99,"<>",KOL_Roster!$H$3:$H$99,"<>No*",KOL_Roster!$H$3:$H$99,"<>*international not verified*",KOL_Roster!$H$3:$H$99,"<>*international oral not verified*") -> 3 | F37: =COUNTIFS(KOL_Roster!$A$3:$A$99,F$33,KOL_Roster!$H$3:$H$99,"<>",KOL_Roster!$H$3:$H$99,"<>No*",KOL_Roster!$H$3:$H$99,"<>*international not verified*",KOL_Roster!$H$3:$H$99,"<>*international oral not verified*") -> 0 | G37: =SUM(B37:F37) -> 5
A38: KOLs flagged as competitor-trial investigators (Engagement priority contains "competitor") | B38: =COUNTIFS(KOL_Roster!$A$3:$A$99,B$33,KOL_Roster!$I$3:$I$99,"*competitor*") -> 2 | C38: =COUNTIFS(KOL_Roster!$A$3:$A$99,C$33,KOL_Roster!$I$3:$I$99,"*competitor*") -> 2 | D38: =COUNTIFS(KOL_Roster!$A$3:$A$99,D$33,KOL_Roster!$I$3:$I$99,"*competitor*") -> 3 | E38: =COUNTIFS(KOL_Roster!$A$3:$A$99,E$33,KOL_Roster!$I$3:$I$99,"*competitor*") -> 2 | F38: =COUNTIFS(KOL_Roster!$A$3:$A$99,F$33,KOL_Roster!$I$3:$I$99,"*competitor*") -> 1 | G38: =SUM(B38:F38) -> 10

Sheet Infrastructure
A1: Infrastructure — Angelman syndrome diagnostic, assessment & treatment requirements mapped to centre tiers (incl. obudanersen IT-ASO overlay)
A2: Domain | B2: Capability | C2: Minimum requirement | D2: Typical Tier 1-2 coverage | E2: Notes / failure modes
A3: DIAGNOSTICS
A4: Diagnostics | B4: Methylation analysis of 15q11.2-q13 (MS-MLPA / methylation-specific PCR) | C4: Access to accredited genetics lab offering MS-MLPA; detects deletion, UPD and imprinting defects | D4: Universal at Tier 1-2 (in-house or regional genetics lab) | E4: Normal methylation does not exclude AS (UBE3A variants); failure mode = stopping work-up after normal methylation.
A5: Diagnostics | B5: Deletion sizing (class I vs II) / CMA; UPD studies (parental microsatellite/SNP); imprinting-centre analysis | C5: CMA + parental samples; IC deletion testing for recurrence counselling | D5: Tier 1 routine; Tier 2 variable (send-out) | E5: Genotype matters: deletion = most severe phenotype (Bindels-de Heus 2020); UPD/ID distinction needed for CHAMPION eligibility (central or qualified local geneticist confirmation).
A6: Diagnostics | B6: UBE3A sequencing (NGS panel/exome) for methylation-normal cases | C6: Clinical NGS with UBE3A coverage + variant interpretation | D6: Tier 1-2 via clinical genetics | E6: Minority genotype; REVEAL includes UBE3A mutation; Aspire excluded it (deletion only).
A7: Diagnostics | B7: Genetic-subtype gating of trial/treatment eligibility | C7: Documented molecular genotype in record | D7: Tier 1-2 hold genotype; older adults often undocumented | E7: REVEAL = deletion or UBE3A mutation only; CHAMPION = UPD/ID only. Undocumented genotype in adults/legacy diagnoses is the main screen-failure driver → re-testing capacity required.
A8: Diagnostics | B8: Clinical diagnosis per Williams 2006 consensus criteria; EEG pattern | C8: Clinician familiar with consistent/frequent/associated features; paediatric EEG | D8: Universal at Tier 1-2 | E8: Characteristic EEG (high-amplitude rhythmic delta) supports diagnosis; misdiagnosis as autism/CP delays testing (Mertz 2013: later diagnosis in non-deletion).
A9: SEVERITY ASSESSMENT
A10: Severity assessment | B10: Bayley-4 (cognition, receptive/expressive communication, gross/fine motor) | C10: Trained psychologist/rater; standardised administration | D10: Tier 1 research centres; Tier 2 limited | E10: REVEAL primary endpoint = Bayley-4 expressive communication; Aspire primary = Bayley-4 cognition. Rater training/reliability a key operational risk (Aspire failed on Bayley-4 cognition).
A11: Severity assessment | B11: Vineland-3 adaptive behaviour | C11: Caregiver interview by trained rater | D11: Tier 1 routine in research; Tier 2 variable | E11: Used in HALOS and Aspire secondaries; language-validated versions needed per country.
A12: Severity assessment | B12: AS-specific global scales (SAS-CGI-S/C, CGI-I-AS) and Angelman Severity Assessment (ASA) | C12: Clinician trained on AS-anchored CGI | D12: Trial sites only | E12: SAS-CGI-C drove HALOS headline (97%); gaboxadol failed on CGI-I-AS — scale sensitivity/placebo response caveat.
A13: Severity assessment | B13: Observer-Reported Communication Ability (ORCA) & caregiver PROs | C13: eCOA/caregiver-report infrastructure | D13: Trial sites | E13: ORCA used in HALOS; translation/cultural validation for EU languages.
A14: Severity assessment | B14: Sleep assessment (diaries, actigraphy) and seizure diaries | C14: Sleep clinic / actigraphy; structured seizure diary | D14: Tier 1 neuropaediatrics/sleep services | E14: Sleep and seizures are top caregiver burdens; prerequisite for stable baseline (REVEAL requires ≥8 weeks stable concomitant meds).
A15: Severity assessment | B15: Quantitative EEG delta-power biomarker | C15: Research-grade EEG acquisition + central quantitative analysis | D15: Tier 1 research centres | E15: HALOS reported reduction in slow-wave delta activity; rugonersen showed partial EEG normalisation; not yet a validated surrogate.
A16: TREATMENT
A17: Treatment (SoC) | B17: Anti-seizure medication management incl. NCSE recognition | C17: Paediatric epileptologist; EEG/video-EEG | D17: Tier 1-2 (EpiCARE HCPs) | E17: High NCSE rate in AS (Bindels-de Heus 2020); ASM selection per Duis 2022 neurology section.
A18: Treatment (SoC) | B18: Sleep management, behaviour, GI/feeding, orthopaedics | C18: Multidisciplinary clinic (Duis 2022 consensus domains) | D18: Tier 1 full MDT; Tier 2 partial | E18: Duis 2022 consensus covers genetics, neurology, sleep, psychiatry, orthopaedics, ophthalmology, communication, therapies, caregiver health.
A19: Treatment (SoC) | B19: AAC / communication therapy; PT/OT | C19: Speech & language therapist with AAC expertise; PT/OT | D19: Variable — often community-based | E19: Expressive communication is REVEAL primary endpoint → AAC-competent SLT input is both SoC and endpoint-relevant.
A20: Treatment — MOST DIFFERENTIATING | B20: Repeat intrathecal ASO administration via lumbar puncture in a non-verbal, often uncooperative paediatric AND adult population | C20: Paediatric day-unit or procedural suite; procedural sedation/GA without intubation (REVEAL/CHAMPION criterion); anaesthesia team experienced with ID/behaviour; imaging (fluoroscopy/US) for difficult spines; CSF sampling; post-LP monitoring; pharmacy handling of IT product | D20: Nusinersen-experienced paediatric neurology / SMA centres (Tier 1-2) — but adult AS administration capacity is thin | E20: Scoliosis/spinal anatomy, obesity/hyperphagia, behavioural distress and seizures complicate LP; Ionis required each REVEAL site to self-certify capability for Cohort 1, Cohort 2 or both — adult-capable sites are fewer. EU sham-skin-prick control still requires full procedural set-up. Lifelong quarterly IT dosing = chronic procedural load.
A21: Treatment — benchmark | B21: Nusinersen (SPINRAZA) IT delivery footprint | C21: Doctor/nurse experienced in IT injection; sedation as needed (EMA EPAR) | D21: Established at SMA treatment centres across EU4+UK since 2017 | E21: Same Ionis IT-ASO paradigm; SMA centres already run repeat-LP lists, sedation pathways and difficult-spine imaging — directly transferable, though SMA vs AS behaviour/anaesthesia profiles differ.
A22: REHABILITATION / CHRONIC MANAGEMENT
