Workbook

Sheet README
A1: Title | B1: EU4+UK Angelman Syndrome Treatment Centres and KOLs — Mapping & Tiering
A2: Prepared for | B2: Medical Affairs workstream — ION582 / obudanersen (Ionis Pharmaceuticals) in Angelman syndrome (AS)
A3: Geographies | B3: EU4+UK: Germany, France, Italy, Spain, United Kingdom. Out of scope (not mapped): EU-rest and Europe-rest — note Poland hosts REVEAL and Aspire sites. The template's Europe-rest tag also lists GB; here the UK is treated as part of EU4+UK only.
A4: Date compiled | B4: 2026-10-14 (public sources searched 14 Oct 2026)
A5: Compiled by | B5: Microsoft Copilot (model tag: Copilot.Sonnet5.5) for Ian Pepper — template: PROMPT_KOL_Centre_Map_v2
A6: Method | B6: Cross-referenced from public sources: trial registries (ClinicalTrials.gov mirrors, CTIS, HRA, AP-HP), sponsor communications, ASF clinic network pages, national guideline (HAS PNDS), peer-reviewed papers, ERN member lists (EpiCARE, Orphanet ITHACA), national patient-association lists. No pharma-supplied or paid-database data. Every KOL and centre is tied to a named source (see Sources_Caveats). No names were invented; gaps are marked 'Not publicly identified — verify locally'.
A7: Asset status snapshot (14 Oct 2026) | B7: ION582 = obudanersen (Ionis; ASO against UBE3A-ATS; intrathecal). FDA Breakthrough Therapy designation (9 Sep 2025); FDA + EMA Orphan, FDA Fast Track / Rare Pediatric designations. Phase 3 REVEAL (NCT06914609; EU CT 2024-519711-33-01): randomised, double-blind, ~158 participants, 80 mg vs control (amended Dec 2025 from three arms); Cohort 1 (pivotal, age 2–<18 y) completed enrolment with 136 participants (6 Jul 2026); Cohort 2 (adults 18–≤50 y) still screening (expected completion Q3 2026); topline expected 2H 2027. EU control arm uses a skin-prick sham procedure. First EU REVEAL sites: LMU München (DE) and Parc Taulí Sabadell (ES) (Apr 2026); further sites planned in DE, IT, PL, ES; UK sites: Oxford and GOSH. Phase 1/2 HALOS (NCT05127226): 71 participants, active-not-recruiting; EU4+UK sites Necker (FR), Pisa (IT), Oxford (UK). CHAMPION (Phase 3 in UPD/imprinting-centre defect) planned. Registry status labels conflict across mirrors (CTIS 'recruiting' vs mirror 'active, not recruiting'; enrolment 156 vs 158) — see Verification_Flags.
A8: TAB GUIDE
A9: README | B9: Scope, five signal pillars, tier definitions (centres and KOLs), caveats, gap-fill method, how-to-use.
A10: Country_Centres | B10: Master flat table: 41 centres (Tier 1–3), one row each; 13 columns; frozen header and autofilter. Tier 4 not enumerated (not requested).
A11: KOL_Roster | B11: 75 named KOLs with role/signal, pillar flags, engagement priority and score-driven KOL Tier (columns K–R hold the scoring; tier is formula-driven).
A12: Tier_Counts | B12: Centre and KOL matrices (country × tier) and cross-cuts — all counts are formulas on the flat tables.
A13: Infrastructure | B13: AS-specific diagnostic / assessment / treatment / rehabilitation / future-state requirements mapped to centre tiers, with the ION582 asset overlay.
A14: Sources_Caveats | B14: Authoritative sources with clickable URLs / DOI / PMID / NCT, plus data-quality caveats.
A15: Verification_Flags | B15: Adversarial QA pass. Flagged source cells are highlighted red (#FFC7CE / #9C0006) on their home sheets — flagged, not auto-corrected.
A16: THE FIVE SIGNAL PILLARS CHOSEN FOR ANGELMAN SYNDROME
A17: P1 — Guideline-author signal | B17: Internationally: Duis et al. 2022, 'A multidisciplinary approach and consensus statement to establish standards of care for Angelman syndrome', Mol Genet Genomic Med 10(3):e1843 (DOI 10.1002/mgg3.1843; ~42 named authors). From the affiliation list retrieved, European authors sit in Erasmus MC (NL) and Queen Fabiola Children's Hospital (BE) — no EU4+UK author identified (list partly truncated; verify). SUBSTITUTION (documented per template): country-level guidelines are used for regional tiering — France: PNDS Angelman (HAS portal, Nov 2021; coordinator Dr Delphine Héron; not validated by HAS). No equivalent DE/IT/ES/UK national guideline was found; UK Manchester lead self-reports guideline involvement (unverified).
A18: P2 — Publication-authorship signal | B18: AS-specific peer-reviewed and trial authorship, last ~5 years, incl. this asset and competitors: ION582 (HALOS NCT05127226, REVEAL NCT06914609); GTX-102/apazunersen, Ultragenyx (Phase 1/2 and Aspire NCT06617429); rugonersen, Roche → Oak Hill Bio (TANGELO NCT04428281, Hipp et al., Nat Med 2025, PMID 40646322; Phase 3 BEACON); alogabat, Roche (Phase 2a). Key EU4+UK papers: Neuropediatrics 2025 (Munich/Leipzig); JADD 2025 (Munich); Epilepsia Open 2024 (Bambino Gesù); IReAS EJMG 2026 and RISA JCM 2024 (Italy); A-MANECE Orphanet J Rare Dis 2018 (Puerta de Hierro); Front Psychiatry 2019 (Birmingham).
A19: P3 — Registry / natural-history / trial-network signal | B19: AS has no single flagship registry. Substituted by: national natural-history and registry studies — FAST UK NatHis (Oxford, NCT05100810), FAST Spain NH (Puerta de Hierro / Parc Taulí, NCT06115109), German AS online register (Leipzig), Italian RISA (FROM Bergamo, NCT03650569; enrolment closed) and IReAS (14 referral centres), UK Manchester AS Register — plus the ION582 trial network (HALOS/REVEAL) and the ASF Clinic Network / LADDER. Coordinator = leads a registry or national study; Site = participating centre.
A20: P4 — Reference-network signal | B20: Primary: ERN-ITHACA (rare malformation syndromes, intellectual and other neurodevelopmental disorders; 71 centres) — AS falls here. Secondary: ERN-EpiCARE (AS epilepsy ≈ 80–90%) and ERN-RND. National equivalents: France CRMR/DéfiScience (Déficiences intellectuelles de causes rares); Italy IRCCS / national rare-disease centre list; Spain CSUR; Germany Zentrum für Seltene Erkrankungen (ZSE) B-centre / SPZ / MZEB; ASF-recognised clinics (foundation 'Centre of Excellence' analogue). UK: N/A (post-Brexit; use NHS specialist-clinic status). ERN membership of several AS clinics (LMU, Leipzig, Parc Taulí, Puerta de Hierro, Stella Maris, Medea) could NOT be confirmed from retrieved lists — marked 'Unconfirmed'.
A21: P5 — Disease-programme signal | B21: A dedicated Angelman clinic / multidisciplinary AS service: ASF clinics (Munich, Leipzig, Aachen, Parc Taulí), Manchester AS Clinic (UK's only specialist AS clinic), and AS-specific units (e.g. Stella Maris Developmental Neurology). 'Partial' = rare-neurodevelopment / epilepsy service without an AS-dedicated clinic.
A22: CENTRE TIER DEFINITIONS
A23: Tier 1 — Anchor / reference | B23: Hosts a P1 guideline author or a P3 registry coordinator, AND is a P4 reference-network HCP (or national equivalent), AND carries the P2 publication signal (disease-, asset- or competitor-trial authorship in the last ~5 years). Role: first-wave KOL engagement; advisory-board core; RWE and observational lead candidates; likely evidence partners. AS CALIBRATION (documented): because no P1 international author sits in EU4+UK, Tier 1 is reached via [P3 coordinator OR lead national clinic/trial hub with pivotal-trial participation OR national P1 guideline (France PNDS)] AND [P4 or national equivalent incl. ASF clinic] AND [P2]. Applied to LMU München, Parc Taulí and Pitié-Salpêtrière — flagged in Verification_Flags.
A24: Tier 2 — National referral | B24: A P4 HCP with the relevant P5 programme, or a P3 participating site; university hospital with full critical/specialist care and disease-relevant diagnostics; recurring P2 authorship on the relevant literature. Role: second-wave outreach; regional referral hubs.
A25: Tier 3 — Tertiary capable | B25: National/regional reference centre or large university hospital with the core treatment infrastructure but typically not research-active in the disease. Role: launch-phase distribution; HCP education; not advisory core.
A26: Tier 4 — Community / acute presentation | B26: Not enumerated (not requested). AS is chronic and care concentrates at specialist clinics and paediatric neurology centres, so the acute-presentation dispersion caveat is omitted. Case-finding / pharmacovigilance for community paediatrics would be addressed through national-society and patient-association channels (Angelman e.V., AngelmanUK, AFSA, OR.S.A., FAST Spain/Angel FOCUS), not individual outreach.
A27: KOL TIER DEFINITIONS (score-driven; template Section 3)
A28: Scoring criteria (1 / 3 / 5 points per domain) | B28: Guideline authorship — 1: contributor to local protocols / co-author of minor or regional guidelines; 3: lead/co-author of national guidelines or contributor to multicentre consensus statements; 5: lead/co-author of international or globally influential guidelines. Publications — 1: ≥3 publications (any authorship) in relevant peer-reviewed journals; 3: ≥5 publications in reputable journals (last 7 years); 5: ≥5 as first/last author (last 7 years). Clinical trials — 1: participant or site investigator in local/national trials; 3: national PI or investigator in multi-country/regional trials (last 7 years); 5: lead/site PI in large international or pivotal trials influencing practice/regulation. Academic appointment — 1: specialist physician / working-group member; 3: senior physician, associate professor, research-group member; 5: department head, research-group leader, emeritus professor. Society roles — 1: member of local/regional society; 3: committee/board member of a national society; 5: executive leadership in major national/international societies. Speaker engagement — 1: occasional local/regional speaker; 3: regular invited speaker at national conferences; 5: keynote/plenary at major international congresses. Awards — 1–2 points depending on calibre.
A29: Scoring rules and tier cut-offs | B29: Each physician is scored independently on all seven domains using the highest level FULLY supported by retrieved evidence; no inference; where evidence is limited the floor score of 1 is assigned (the template's default) — including Awards (1) and Speaker (1). Total = sum (formula, column R). Tier 1 (Top KOLs): 24–30 points; Tier 2 (Established): 12–23; Tier 3 (Emerging/Local): 0–11. IMPORTANT: scores here are EVIDENCE-FLOOR scores from web sources only (no PubMed counts, CVs or congress programmes were pulled), so most KOLs fall in Tier 2/3 and no KOL reaches Tier 1. 'Engagement priority' (column I) is a separate, qualitative field tied to centre tier and ION582 relevance. Re-score after PubMed / congress-abstract / CV enrichment.
A30: CRITICAL CAVEATS
A31: No EU4+UK international guideline author | B31: No EU4+UK author was identified in the Duis 2022 consensus (only Erasmus MC NL and Queen Fabiola BE among European affiliations retrieved). P1 therefore rests on the French PNDS (national) — see Verification_Flags #14.
A32: France is not (yet) a REVEAL country | B32: Ionis named Germany, Italy, Poland and Spain for EU REVEAL expansion (Apr 2026); France is absent although Necker was a HALOS site. UK has two REVEAL sites (Oxford, GOSH).
A33: Competitor read-through | B33: GTX-102 (apazunersen) Phase 3 Aspire reportedly missed its primary and key secondary endpoints (2 Sep 2026; single secondary source — verify against the Ultragenyx release). Aspire sites (LMU, Leipzig, UKE, SJD, Parc Taulí, Puerta de Hierro, Virgen del Rocío) are ASO-experienced and may be capacity-available. Rugonersen (Oak Hill Bio) is in Phase 3 BEACON (first participant dosed 28 Jul 2026 per FAST news).
A34: Post-Brexit UK | B34: P4 = N/A for all UK centres (Manchester founded ERN-ITHACA in 2017 but coordination moved to AP-HP in Nov 2018). Tiered on national specialist-clinic and trial signal. UK Tier 3 not enumerated (no sourced designation).
A35: Provenance limits | B35: Italian Tier 3 rows rely on a patient-association centre list (OR.S.A.); IReAS participating-centre list (14 centres) is not public; several KOL affiliations are not stated in the source and are marked 'verify'. Conference-presentation evidence was not retrieved for any KOL.
A36: KOL gap-fill methodology | B36: Order followed: (a) P2 senior/corresponding authors on AS or competitor-trial papers (Neuropediatrics 2025, A-MANECE, Epilepsia Open 2024, IReAS, RISA, TANGELO); (b) reference-network coordinators (ERN-ITHACA, EpiCARE, CRMR Lyon/Lille, SEGCD contacts); (c) national patient-association and ASF-clinic rosters (OR.S.A., ASF clinics, AngelmanUK experts, FAST); (d) hospital directories — attempted only where a centre was named (not exhaustive). Where nothing traceable: 'Not publicly identified — verify locally'.
A37: KOL minimum (≥15 per country) | B37: Met for Germany (15), Italy (22), Spain (15). NOT met for France (9) and United Kingdom (14) despite searching — shortfall disclosed rather than padded; see Verification_Flags #17.
A38: HOW TO USE
A39: Field deployment | B39: Sort Country_Centres by Tier ascending then Country; start with the nine Tier 1 centres. For ION582 sequencing: (1) active/near-active REVEAL and HALOS sites (Stella Maris, Oxford, Necker, LMU, Parc Taulí, Besta, Medea, Bambino Gesù, GOSH) for evidence and advisory input; (2) natural-history / registry coordinators (Oxford, Puerta de Hierro, Leipzig, Manchester, RISA/IReAS) for RWE; (3) ASF clinics and CRMR/ERN partners for referral pathways and launch readiness.
A40: Trial-site shortlist | B40: Filter Country_Centres: P3 flag begins 'Coordinator' or 'Site' AND P2 flag contains 'trial' (Yes — ION582 trial / Yes — competitor trial). Competitor-trial sites (Aspire, TANGELO, GTX-102 Phase 1/2) are trial-ready but check confidentiality and capacity.
...

Sheet Country_Centres
A1: Country | B1: Tier | C1: City | D1: Centre / Hospital | E1: Unit / Department | F1: KOL / Lead clinician(s) | G1: Role / Affiliation signal | H1: P1 — AS guideline author (international / national) | I1: P2 — AS publication / trial author (5y): disease / ION582 / competitor | J1: P3 — Registry / natural-history / trial network (coord / site) | K1: P4 — ERN / national reference HCP | L1: P5 — Angelman programme / clinic | M1: Notes
A2: Germany | B2: 1 | C2: München | D2: LMU Klinikum — Dr. von Haunersches Kinderspital | E2: iSPZ Hauner — Angelman Zentrum München (AZM); Pediatric Neurology, Developmental Medicine & Social Pediatrics | F2: Dr. Christine Makowski (AZM lead); Dr. Lena Manssen; PD Dr. Cornelia von Hagen; Heike Weigand; Ingo Borggraefe | G2: First German AS centre (2019/20); ASF-recognised clinic and member of the LADDER network; first EU REVEAL site activated (LMU, Apr 2026); Haunersche Kinderklinik is an Aspire (GTX-102) site; co-authors of Neuropediatrics 2025 AS review and JADD 2025 family-impact study. | H2: No (no EU4+UK author identified in the Duis 2022 consensus affiliation list retrieved) | I2: Yes — disease (Neuropediatrics 2025; J Autism Dev Disord 2025); Yes — ION582 trial (REVEAL EU site); Yes — competitor trial (GTX-102 Aspire) | J2: Site — LADDER network / clinical-data hub; REVEAL and Aspire site (no registry coordinator role) | K2: Unconfirmed — ERN-ITHACA / EpiCARE membership not found; national equivalent: ASF clinic | L2: Yes | M2: Tier 1 via AS calibration (lead clinical hub + pivotal-trial site; see README). Affiliation of Makowski moved from München Klinik Schwabing / kbo (2021 flyer) to LMU iSPZ Hauner (current LMU and ASF pages). Paediatric 0–18 y; adults referred to a collaborating clinic (AZA Aachen).
A3: Germany | B3: 1 | C3: Leipzig | D3: Universitätsklinikum Leipzig | E3: Angelman Zentrum Leipzig (AZL): SPZ / Neuropädiatrie (Klinik für Kinder- und Jugendmedizin) + Institut für Humangenetik | F3: Dr. Janina Gburek-Augustat (AZL clinic lead); Prof. Andreas Merkenschlager; Prof. Johannes Lemke; Dr. Ilona Krey; Dr. Eckehard Schumann | G3: AZL opened Dec 2022 (third German AS centre); Human Genetics hosts the German AS online patient register (contacts Lemke, Krey); integrated B-centre of the University Rare Disease Centre Leipzig (se-atlas); Aspire site (University of Leipzig); co-authors of Neuropediatrics 2025 AS review. | H3: No (no EU4+UK author identified in the Duis 2022 consensus affiliation list retrieved) | I3: Yes — disease (Neuropediatrics 2025); Yes — competitor trial (GTX-102 Aspire) | J3: Coordinator — German Angelman online register (University of Leipzig Medical Center); Aspire site | K3: Qualified — national equivalent: integrated B-centre, University Rare Disease Centre Leipzig (se-atlas); ERN membership not confirmed | L3: Yes | M3: Not listed as an EU REVEAL site in the April 2026 Ionis letter (Germany expansion planned — verify). Register enrolment mechanics and site count not public.
A4: Germany | B4: 2 | C4: Aachen | D4: Uniklinik RWTH Aachen | E4: MZEB — Angelman Zentrum Aachen (AZA, adults) | F4: Dr. Andrea Maier (AZA lead, Neurology) | G4: First adult-focused AS centre in Germany (founded 2021 with Angelman e.V.); ASF-recognised clinic; works with AZM so new therapies can be applied quickly. | H4: No | I4: No (no AS publication or trial signal retrieved) | J4: No | K4: Unconfirmed — MZEB model for adults with intellectual/multiple disabilities; national equivalent: ASF clinic | L4: Yes | M4: Key for adult cohort (REVEAL Cohort 2, 18–≤50 y) and post-paediatric transition. Research activity: 'current studies' page referenced but not retrieved.
A5: Germany | B5: 2 | C5: Hamburg | D5: Universitätsklinikum Hamburg-Eppendorf (UKE) | E5: Klinik für Kinder- und Jugendmedizin (Kinder-UKE); Institute of Human Genetics (genetic-counselling HCP) | F5: Prof. Ania C. Muntau (Director, Kinderklinik) — Not publicly identified — verify locally (Aspire investigator) | G5: Aspire (GTX-102) Phase 3 site; ERN-ITHACA HCP (genetic counselling, Orphanet list updated Mar 2022). | H5: No | I5: Yes — competitor trial (GTX-102 Aspire) | J5: Site — Aspire (competitor Phase 3) | K5: Yes — ERN-ITHACA HCP (genetic counselling; Orphanet Mar-2022 — verify current) | L5: Partial | M5: Muntau is named as clinic director with a rare-disease research profile; her role in Aspire is not confirmed. Not a REVEAL site in public sources.
A6: Germany | B6: 3 | C6: Tübingen | D6: Universitätsklinikum Tübingen | E6: Epilepsy Dept (ERN-EpiCARE); Institut für Medizinische Genetik und angewandte Genomik (ERN-ITHACA HCP) | F6: Not publicly identified — verify locally | G6: Network membership only: EpiCARE member list and Orphanet ITHACA list. | H6: No | I6: No | J6: No | K6: Yes — ERN-EpiCARE / ERN-ITHACA | L6: No | M6: No AS-specific signal retrieved; tertiary infrastructure only (AS epilepsy ≈ 80–90%).
A7: Germany | B7: 3 | C7: Erlangen | D7: Universitätsklinikum Erlangen | E7: Epilepsy Center (ERN-EpiCARE); ZSE Erlangen — Zentrum für Seltene Entwicklungsstörungen (ERN-ITHACA) | F7: Not publicly identified — verify locally | G7: Network membership only. | H7: No | I7: No | J7: No | K7: Yes — ERN-EpiCARE / ERN-ITHACA | L7: No | M7: No AS-specific signal retrieved.
A8: Germany | B8: 3 | C8: Bonn | D8: Universitätsklinikum Bonn | E8: Department of Epileptology (ERN-EpiCARE) | F8: Not publicly identified — verify locally | G8: Network membership only. | H8: No | I8: No | J8: No | K8: Yes — ERN-EpiCARE | L8: No | M8: No AS-specific signal retrieved.
A9: Germany | B9: 3 | C9: Freiburg | D9: Universitätsklinikum Freiburg | E9: Epilepsy Centre, Neurocenter (ERN-EpiCARE) | F9: Not publicly identified — verify locally | G9: Network membership only. | H9: No | I9: No | J9: No | K9: Yes — ERN-EpiCARE | L9: No | M9: No AS-specific signal retrieved.
A10: France | B10: 1 | C10: Paris | D10: AP-HP — Hôpital Necker-Enfants Malades | E10: Neuropédiatrie; Pediatric Radiology (EYEANGEL) | F10: Nadia Bahi-Buisson (HALOS coordinating investigator; FAST Scientific Advisory Board); Prof. Nathalie Boddaert (EYEANGEL lead) | G10: HALOS (ION582 Phase 1/2) French site — coordinating investigator Bahi-Buisson (AP-HP registry); first EU HALOS patient enrolled in France (2023 press); EYEANGEL AS eye-tracking study (FAST France-funded); ERN-EpiCARE full member. | H10: No (national PNDS was authored by the Pitié-Salpêtrière coordinating centre) | I10: Yes — ION582 trial (HALOS); Yes — disease (EYEANGEL AS eye-tracking study, AP-HP) | J10: Coordinator — HALOS French coordinating investigator; EYEANGEL | K10: Yes — ERN-EpiCARE full member (CRMR / DéfiScience status to verify) | L10: Partial | M10: HALOS is closed to inclusions (AP-HP registry; trial 'active, not recruiting'). France is NOT among the EU countries named for REVEAL activation (DE, IT, PL, ES — Apr 2026) — gap for ION582 Phase 3.
A11: France | B11: 1 | C11: Paris | D11: AP-HP Sorbonne Université — Hôpital Pitié-Salpêtrière | E11: Centre de Référence Coordonnateur « Déficiences Intellectuelles de causes rares » (DéfiScience); Génétique | F11: Dr. Delphine Héron (coordinator; PNDS Angelman) | G11: Authored the national PNDS Angelman (Nov 2021) and its argumentaire; coordinating centre for 12 reference + 11 competence centres of the DI-rare-causes network; ERN-EpiCARE éPiRaReS consortium member. | H11: Yes — national guideline (PNDS Angelman, Nov 2021; not validated by HAS) | I11: Yes — disease (PNDS 2021 + argumentaire); AS peer-reviewed output not verified | J11: No (no AS registry / trial role retrieved) | K11: Yes — national reference centre (CRMR coordinating centre); EpiCARE éPiRaReS consortium | L11: Yes | M11: Tier 1 via national P1 equivalent (no P3 coordinator). The PNDS and a national 'Angelman emergency card' exist. Not a trial site in retrieved sources.
A12: France | B12: 2 | C12: Paris | D12: AP-HP — Hôpital Robert-Debré | E12: Clinical Genetics; ERN-ITHACA Coordinating Centre; EpiCARE éPiRaReS consortium | F12: Prof. Alain Verloes (ERN-ITHACA coordinator) | G12: Hosts the ERN-ITHACA coordinating centre (coordination moved from Manchester to AP-HP in Nov 2018); EpiCARE éPiRaReS consortium. | H12: No | I12: No (no AS-specific publication or trial retrieved) | J12: No | K12: Yes — ERN-ITHACA coordinating centre | L12: Partial | M12: Network-level partner for cross-border case discussion (CPMS); not an AS clinic.
A13: France | B13: 2 | C13: Bron (Lyon) | D13: Hospices Civils de Lyon — Hôpital Femme Mère Enfant | E13: Centre de référence constitutif DI de causes rares (CRDI); Epilepsy Dept | F13: Pr Vincent des Portes; Dr Aurore Curie; Dr Christelle Rougeot-Jung | G13: Reference centre (relabelled 2023) in DéfiScience; ERN-ITHACA member; EpiCARE member (Lyon epilepsy departments). | H13: No | I13: No (no AS-specific publication or trial retrieved) | J13: No | K13: Yes — ERN-ITHACA member; ERN-EpiCARE | L13: Partial | M13: Covers all rare-cause intellectual disability; AS-specific programme not confirmed. Prof. Arzimanoglou formerly led Lyon paediatric epileptology (to 2023) — now Barcelona.
... A42: United Kingdom | B42: 2 | C42: London | D42: Great Ormond Street Hospital for Children NHS FT | E42: Neurology; Clinical Genetics | F42: Not publicly identified — verify locally (REVEAL PI); Prof. Helen Cross (EpiCARE founder-lead; GOSH affiliation inferred — verify) | G42: Second UK REVEAL site (FAST UK post); GOSH was appointed lead centre of ERN-EpiCARE at its 2017 launch (pre-Brexit). | H42: No | I42: Yes — ION582 trial (REVEAL) | J42: Site — REVEAL | K42: N/A (post-Brexit) | L42: Partial | M42: REVEAL activation evidenced only by a FAST UK social-media post — verify on ClinicalTrials.gov / HRA. UK Tier 3 not enumerated: no sourced national designation.

Sheet KOL_Roster
A1: Country | B1: KOL | C1: Primary affiliation | D1: Role / Signal | E1: [P1] Guideline author | F1: [P3] Registry role | G1: Key publications / datasets [P2] (disease, asset and competitor trials) | H1: Presentation at international conferences | I1: Engagement priority | J1: KOL Tier for TOV (formula) | K1: Guideline pts | L1: Publications pts | M1: Clinical-trial pts | N1: Academic pts | O1: Society pts | P1: Speaker pts | Q1: Award pts | R1: Total score (formula) | S1: Evidence sources
A2: Germany | B2: Dr. Christine Makowski | C2: LMU Klinikum — Dr. von Haunersches Kinderspital, iSPZ Hauner (Angelman Zentrum München) | D2: Lead of AZM (ASF clinic; LADDER network); pediatric neurologist / epileptologist; REVEAL EU first-site institution; Aspire site institution. | E2: No | F2: Site — LADDER network / AZM clinical-data hub | G2: Disease: Neuropediatrics 2025 (Manssen…Makowski); J Autism Dev Disord 2025 (Pfarrer…Makowski) | Trial (ION582): LMU REVEAL site (PI not confirmed) | Trial (competitor): Haunersche Kinderklinik Aspire site | H2: Not verified — no conference abstract retrieved | I2: TIER 1 — must-engage (ION582-specific) | J2: =IF(R2>=24,1,IF(R2>=12,2,3)) -> 3 | K2: 1 | L2: 1 | M2: 3 | N2: 3 | O2: 1 | P2: 1 | Q2: 1 | R2: =SUM(K2:Q2) -> 11 | S2: ASF clinic page; LMU AZM page; Ionis EU letter Apr 2026; Thieme Neuropediatrics 2025; LMU epub JADD 2025
A3: Germany | B3: Dr. Lena Manssen | C3: LMU Klinikum — Dr. von Haunersches Kinderspital (iSPZ Hauner) | D3: AZM physician; joint first/corresponding author of 'Precision Medicine in Angelman Syndrome' (Neuropediatrics 2025). | E3: No | F3: No | G3: Disease: Neuropediatrics 2025 (joint first author); JADD 2025 | H3: Not verified — no conference abstract retrieved | I3: TIER 2 — engage | J3: =IF(R3>=24,1,IF(R3>=12,2,3)) -> 3 | K3: 1 | L3: 1 | M3: 1 | N3: 1 | O3: 1 | P3: 1 | Q3: 1 | R3: =SUM(K3:Q3) -> 7 | S3: Thieme Neuropediatrics 2025; LMU epub
A4: Germany | B4: PD Dr. Cornelia von Hagen | C4: LMU Klinikum (Hauner) / kbo-Kinderzentrum München gGmbH | D4: Psychology lead of AZM per 2021 AZM flyer; co-author Neuropediatrics 2025 and JADD 2025. | E4: No | F4: No | G4: Disease: Neuropediatrics 2025; JADD 2025 | H4: Not verified — no conference abstract retrieved | I4: TIER 2 — engage | J4: =IF(R4>=24,1,IF(R4>=12,2,3)) -> 3 | K4: 1 | L4: 1 | M4: 1 | N4: 3 | O4: 1 | P4: 1 | Q4: 1 | R4: =SUM(K4:Q4) -> 9 | S4: AZM flyer 2021; Thieme Neuropediatrics 2025
A5: Germany | B5: Heike Weigand | C5: LMU Klinikum — Dr. von Haunersches Kinderspital | D5: Co-author, Neuropediatrics 2025 AS review (Division of Pediatric Neurology, Developmental Medicine & Social Pediatrics). | E5: No | F5: No | G5: Disease: Neuropediatrics 2025 | H5: Not verified — no conference abstract retrieved | I5: TIER 3 — monitor | J5: =IF(R5>=24,1,IF(R5>=12,2,3)) -> 3 | K5: 1 | L5: 1 | M5: 1 | N5: 1 | O5: 1 | P5: 1 | Q5: 1 | R5: =SUM(K5:Q5) -> 7 | S5: Thieme Neuropediatrics 2025
A6: Germany | B6: Ingo Borggraefe | C6: LMU Klinikum — Dr. von Haunersches Kinderspital | D6: Co-author, JADD 2025 behavioural-problems / family-impact study in AS. | E6: No | F6: No | G6: Disease: JADD 2025 | H6: Not verified — no conference abstract retrieved | I6: TIER 3 — monitor | J6: =IF(R6>=24,1,IF(R6>=12,2,3)) -> 3 | K6: 1 | L6: 1 | M6: 1 | N6: 1 | O6: 1 | P6: 1 | Q6: 1 | R6: =SUM(K6:Q6) -> 7 | S6: LMU epub (JADD 2025)
A7: Germany | B7: Prof. Volker Mall | C7: kbo-Kinderzentrum München gGmbH (SPZ); TU München (chair of social paediatrics per 2021 flyer) | D7: Ärztlicher Direktor kbo-Kinderzentrum — listed in 2021 AZM flyer (initiative partner of Angelman e.V.). Current role to verify. | E7: No | F7: No | G7: None retrieved | H7: Not verified — no conference abstract retrieved | I7: TIER 2 — engage — verify current role | J7: =IF(R7>=24,1,IF(R7>=12,2,3)) -> 3 | K7: 1 | L7: 1 | M7: 1 | N7: 5 | O7: 1 | P7: 1 | Q7: 1 | R7: =SUM(K7:Q7) -> 11 | S7: AZM flyer 2021
A8: Germany | B8: Prof. Stefan Burdach | C8: München Klinik Schwabing — Klinik und Poliklinik für Kinder- und Jugendmedizin (per 2021 flyer) | D8: Chefarzt named on 2021 AZM flyer (original AZM host). Current role / affiliation to verify (AZM moved to LMU). | E8: No | F8: No | G8: None retrieved | H8: Not verified — no conference abstract retrieved | I8: TIER 3 — monitor — verify current role | J8: =IF(R8>=24,1,IF(R8>=12,2,3)) -> 3 | K8: 1 | L8: 1 | M8: 1 | N8: 5 | O8: 1 | P8: 1 | Q8: 1 | R8: =SUM(K8:Q8) -> 11 | S8: AZM flyer 2021
A9: Germany | B9: Dr. Janina Gburek-Augustat | C9: Universitätsklinikum Leipzig — SPZ / Neuropädiatrie (Angelman Zentrum Leipzig) | D9: AZL clinic lead (ASF clinic contact); co-author Neuropediatrics 2025; Aspire site (University of Leipzig). | E9: No | F9: Site — AZL clinical lead; Aspire site | G9: Disease: Neuropediatrics 2025 | Trial (competitor): University of Leipzig Aspire site (PI not confirmed) | H9: Not verified — no conference abstract retrieved | I9: TIER 1 — must-engage (registry/clinic hub) | J9: =IF(R9>=24,1,IF(R9>=12,2,3)) -> 3 | K9: 1 | L9: 1 | M9: 3 | N9: 3 | O9: 1 | P9: 1 | Q9: 1 | R9: =SUM(K9:Q9) -> 11 | S9: ASF clinic page; AZL flyer 2025; Thieme Neuropediatrics 2025; ichgcp NCT06617429
A10: Germany | B10: Prof. Andreas Merkenschlager | C10: Universitätsklinikum Leipzig — Neuropädiatrie / Epileptologie | D10: AZL team (neuropaediatrics / epileptology / social medicine); co-author Neuropediatrics 2025. | E10: No | F10: Site — AZL | G10: Disease: Neuropediatrics 2025 | H10: Not verified — no conference abstract retrieved | I10: TIER 2 — engage | J10: =IF(R10>=24,1,IF(R10>=12,2,3)) -> 3 | K10: 1 | L10: 1 | M10: 1 | N10: 3 | O10: 1 | P10: 1 | Q10: 1 | R10: =SUM(K10:Q10) -> 9 | S10: AZL flyer 2025; Thieme Neuropediatrics 2025
A11: Germany | B11: Prof. Johannes R. Lemke | C11: Universitätsklinikum Leipzig — Institut für Humangenetik; Center for Rare Diseases | D11: Contact for human genetics and the Angelman online register (Leipzig); senior co-author Neuropediatrics 2025. | E11: No | F11: Coordinator — German Angelman online register (Leipzig) | G11: Disease: Neuropediatrics 2025 | H11: Not verified — no conference abstract retrieved | I11: TIER 1 — must-engage (registry) | J11: =IF(R11>=24,1,IF(R11>=12,2,3)) -> 3 | K11: 1 | L11: 1 | M11: 1 | N11: 3 | O11: 1 | P11: 1 | Q11: 1 | R11: =SUM(K11:Q11) -> 9 | S11: AZL flyer 2025; Thieme Neuropediatrics 2025
A12: Germany | B12: Dr. Ilona Krey | C12: Universitätsklinikum Leipzig — Institut für Humangenetik | D12: Register contact (Angelman online register); joint first author Neuropediatrics 2025. | E12: No | F12: Coordinator — German Angelman online register (operational contact) | G12: Disease: Neuropediatrics 2025 (joint first author) | H12: Not verified — no conference abstract retrieved | I12: TIER 2 — engage | J12: =IF(R12>=24,1,IF(R12>=12,2,3)) -> 3 | K12: 1 | L12: 1 | M12: 1 | N12: 1 | O12: 1 | P12: 1 | Q12: 1 | R12: =SUM(K12:Q12) -> 7 | S12: AZL flyer 2025; Thieme Neuropediatrics 2025
A13: Germany | B13: Dr. Eckehard Schumann | C13: Universitätsklinikum Leipzig — neuropädiatrische Station J2-1 | D13: Organises inpatient admissions for AZL. | E13: No | F13: No | G13: None retrieved | H13: Not verified — no conference abstract retrieved | I13: TIER 3 — monitor | J13: =IF(R13>=24,1,IF(R13>=12,2,3)) -> 3 | K13: 1 | L13: 1 | M13: 1 | N13: 1 | O13: 1 | P13: 1 | Q13: 1 | R13: =SUM(K13:Q13) -> 7 | S13: AZL flyer 2025
... A76: United Kingdom | B76: Jo Moss | C76: University of Surrey (per Google Scholar co-author listing — verify) | D76: Long-term Cerebra Centre collaborator on AS behavioural phenotype (psychologist). | E76: No | F76: No | G76: Disease: AS behavioural-phenotype chapter (Oliver 2013) | H76: Not verified — no conference abstract retrieved | I76: TIER 3 — monitor | J76: =IF(R76>=24,1,IF(R76>=12,2,3)) -> 3 | K76: 1 | L76: 1 | M76: 1 | N76: 1 | O76: 1 | P76: 1 | Q76: 1 | R76: =SUM(K76:Q76) -> 7 | S76: Oliver et al. 2013 chapter; Google Scholar

Sheet Tier_Counts
A1: Tier counts — EU4+UK Angelman syndrome (ION582)
A3: A. CENTRES — country × tier matrix (formulas on Country_Centres)
A4: Country | B4: Tier 1 | C4: Tier 2 | D4: Tier 3 | E4: Tier 4 | F4: Total enumerated | G4: Notes
A5: Germany | B5: =COUNTIFS(Country_Centres!$A$2:$A$42,$A5,Country_Centres!$B$2:$B$42,1) -> 2 | C5: =COUNTIFS(Country_Centres!$A$2:$A$42,$A5,Country_Centres!$B$2:$B$42,2) -> 2 | D5: =COUNTIFS(Country_Centres!$A$2:$A$42,$A5,Country_Centres!$B$2:$B$42,3) -> 4 | E5: =COUNTIFS(Country_Centres!$A$2:$A$42,$A5,Country_Centres!$B$2:$B$42,4) -> 0 | F5: =SUM(B5:E5) -> 8 | G5: Three ASF clinics anchor care (Munich 0–18 y, Leipzig, Aachen adults). Munich is the first EU REVEAL site; Munich, Leipzig and UKE are Aspire sites. ERN membership of the ASF clinics unconfirmed. Leipzig hosts the German AS register.
A6: France | B6: =COUNTIFS(Country_Centres!$A$2:$A$42,$A6,Country_Centres!$B$2:$B$42,1) -> 2 | C6: =COUNTIFS(Country_Centres!$A$2:$A$42,$A6,Country_Centres!$B$2:$B$42,2) -> 3 | D6: =COUNTIFS(Country_Centres!$A$2:$A$42,$A6,Country_Centres!$B$2:$B$42,3) -> 3 | E6: =COUNTIFS(Country_Centres!$A$2:$A$42,$A6,Country_Centres!$B$2:$B$42,4) -> 0 | F6: =SUM(B6:E6) -> 8 | G6: Only EU4 country with a national AS guideline (PNDS 2021, Pitié-Salpêtrière). Necker = HALOS site. No REVEAL site named — expansion gap. Tier 3 are EpiCARE members without AS signal.
A7: Italy | B7: =COUNTIFS(Country_Centres!$A$2:$A$42,$A7,Country_Centres!$B$2:$B$42,1) -> 1 | C7: =COUNTIFS(Country_Centres!$A$2:$A$42,$A7,Country_Centres!$B$2:$B$42,2) -> 5 | D7: =COUNTIFS(Country_Centres!$A$2:$A$42,$A7,Country_Centres!$B$2:$B$42,3) -> 9 | E7: =COUNTIFS(Country_Centres!$A$2:$A$42,$A7,Country_Centres!$B$2:$B$42,4) -> 0 | F7: =SUM(B7:E7) -> 15 | G7: Widest ION582 footprint: Stella Maris (HALOS PI) plus four named REVEAL centres; two registries (RISA, IReAS). Tier 3 largely from a patient-association list.
A8: Spain | B8: =COUNTIFS(Country_Centres!$A$2:$A$42,$A8,Country_Centres!$B$2:$B$42,1) -> 2 | C8: =COUNTIFS(Country_Centres!$A$2:$A$42,$A8,Country_Centres!$B$2:$B$42,2) -> 2 | D8: =COUNTIFS(Country_Centres!$A$2:$A$42,$A8,Country_Centres!$B$2:$B$42,3) -> 3 | E8: =COUNTIFS(Country_Centres!$A$2:$A$42,$A8,Country_Centres!$B$2:$B$42,4) -> 0 | F8: =SUM(B8:E8) -> 7 | G8: Two Tier 1 hubs (Parc Taulí ASF clinic; Puerta de Hierro natural-history coordinator); SJD and Virgen del Rocío are Aspire/TANGELO sites; Tier 3 = EpiCARE members.
A9: United Kingdom | B9: =COUNTIFS(Country_Centres!$A$2:$A$42,$A9,Country_Centres!$B$2:$B$42,1) -> 2 | C9: =COUNTIFS(Country_Centres!$A$2:$A$42,$A9,Country_Centres!$B$2:$B$42,2) -> 1 | D9: =COUNTIFS(Country_Centres!$A$2:$A$42,$A9,Country_Centres!$B$2:$B$42,3) -> 0 | E9: =COUNTIFS(Country_Centres!$A$2:$A$42,$A9,Country_Centres!$B$2:$B$42,4) -> 0 | F9: =SUM(B9:E9) -> 3 | G9: P4 N/A (post-Brexit). Manchester (only specialist AS clinic), Oxford (NatHis + HALOS/REVEAL) and GOSH (REVEAL). UK Tier 3 not enumerated.
A10: TOTAL | B10: =SUBTOTAL(9,B5:B9) -> 9 | C10: =SUBTOTAL(9,C5:C9) -> 13 | D10: =SUBTOTAL(9,D5:D9) -> 19 | E10: =SUBTOTAL(9,E5:E9) -> 0 | F10: =SUBTOTAL(9,F5:F9) -> 41 | G10: Reconciles to Country_Centres row count (check cell below).
A11: Reconciliation check (rows in Country_Centres) | F11: =COUNTA(Country_Centres!$A$2:$A$42) -> 41 | G11: =IF(F11=F10,"OK — matrix reconciles to flat table","MISMATCH") -> OK — matrix reconciles to flat table
A13: B. CENTRE CROSS-CUTS (formulas on Country_Centres)
A14: Cross-cut | B14: Count | G14: Definition
A15: Centres hosting a P1 guideline author (national or international) | B15: =COUNTIF(Country_Centres!$H$2:$H$42,"Yes*") -> 1 | G15: P1 flag begins 'Yes' (France PNDS only). Qualified (Manchester, self-reported) counted below.
A16: Centres with a qualified P1 (self-reported / unverified) | B16: =COUNTIF(Country_Centres!$H$2:$H$42,"Qualified*") -> 1 | G16: Manchester — authorship unverified.
A17: Centres with P2 disease publication authorship | B17: =COUNTIF(Country_Centres!$I$2:$I$42,"*disease*") -> 13 | G17: P2 flag mentions disease publication / study.
A18: Centres with ION582 trial authorship / role (HALOS or REVEAL) | B18: =COUNTIF(Country_Centres!$I$2:$I$42,"*ION582*") -> 9 | G18: P2 flag mentions ION582 trial.
A19: Centres with competitor-trial authorship / role | B19: =COUNTIF(Country_Centres!$I$2:$I$42,"*competitor*") -> 8 | G19: GTX-102 (Phase 1/2, Aspire), rugonersen (TANGELO).
A20: Centres with either ION582 or competitor-trial role | B20: =SUMPRODUCT(--((ISNUMBER(SEARCH("ION582",Country_Centres!$I$2:$I$42))+ISNUMBER(SEARCH("competitor",Country_Centres!$I$2:$I$42)))>0)) -> 14 | G20: Union of the two rows above (trial-ready shortlist).
A21: Centres with a P3 coordinator role | B21: =COUNTIF(Country_Centres!$J$2:$J$42,"Coordinator*") -> 6 | G21: Registry / natural-history / national-lead investigator.
A22: Centres listed as P3 sites | B22: =COUNTIF(Country_Centres!$J$2:$J$42,"Site*") -> 11 | G22: Participating (non-coordinating) sites.
A23: Centres that are P4 HCPs (ERN or national reference) | B23: =COUNTIF(Country_Centres!$K$2:$K$42,"Yes*") -> 25 | G23: Confirmed from member lists; 'Unconfirmed' rows excluded.
A24: Centres with an explicit P5 AS programme | B24: =COUNTIF(Country_Centres!$L$2:$L$42,"Yes*") -> 8 | G24: ASF clinics, Manchester clinic, AS-dedicated units.
A26: C. KOLs — country × tier matrix (formulas on KOL_Roster; tier = score-driven)
A27: Country | B27: Tier 1 | C27: Tier 2 | D27: Tier 3 | E27: Total enumerated | G27: Notes
A28: Germany | B28: =COUNTIFS(KOL_Roster!$A$2:$A$76,$A28,KOL_Roster!$J$2:$J$76,1) -> 0 | C28: =COUNTIFS(KOL_Roster!$A$2:$A$76,$A28,KOL_Roster!$J$2:$J$76,2) -> 0 | D28: =COUNTIFS(KOL_Roster!$A$2:$A$76,$A28,KOL_Roster!$J$2:$J$76,3) -> 15 | E28: =SUM(B28:D28) -> 15 | G28: 15 named (Munich LMU/kbo, Leipzig, Aachen, UKE, scientific voice). Two names (Mall, Burdach) from a 2021 flyer — verify currency.
A29: France | B29: =COUNTIFS(KOL_Roster!$A$2:$A$76,$A29,KOL_Roster!$J$2:$J$76,1) -> 0 | C29: =COUNTIFS(KOL_Roster!$A$2:$A$76,$A29,KOL_Roster!$J$2:$J$76,2) -> 4 | D29: =COUNTIFS(KOL_Roster!$A$2:$A$76,$A29,KOL_Roster!$J$2:$J$76,3) -> 5 | E29: =SUM(B29:D29) -> 9 | G29: 9 named — BELOW the 15 minimum (disclosed). Core: Necker (Bahi-Buisson, Boddaert), Pitié (Héron), ERN-ITHACA (Verloes), Lyon/Lille CRDI teams. Pull the DéfiScience competence-centre list to close the gap.
A30: Italy | B30: =COUNTIFS(KOL_Roster!$A$2:$A$76,$A30,KOL_Roster!$J$2:$J$76,1) -> 0 | C30: =COUNTIFS(KOL_Roster!$A$2:$A$76,$A30,KOL_Roster!$J$2:$J$76,2) -> 1 | D30: =COUNTIFS(KOL_Roster!$A$2:$A$76,$A30,KOL_Roster!$J$2:$J$76,3) -> 21 | E30: =SUM(B30:D30) -> 22 | G30: 22 named (REVEAL investigators, HALOS PI, IReAS/RISA authors, patient-association-listed clinicians). Several IReAS authors need affiliation verification.
A31: Spain | B31: =COUNTIFS(KOL_Roster!$A$2:$A$76,$A31,KOL_Roster!$J$2:$J$76,1) -> 0 | C31: =COUNTIFS(KOL_Roster!$A$2:$A$76,$A31,KOL_Roster!$J$2:$J$76,2) -> 4 | D31: =COUNTIFS(KOL_Roster!$A$2:$A$76,$A31,KOL_Roster!$J$2:$J$76,3) -> 11 | E31: =SUM(B31:D31) -> 15 | G31: 15 named; 9 of them are A-MANECE co-authors (Puerta de Hierro) with low individual scores. Key: Roche, Ramírez Mallafré, Ruiz-Antorán, Serrano.
A32: United Kingdom | B32: =COUNTIFS(KOL_Roster!$A$2:$A$76,$A32,KOL_Roster!$J$2:$J$76,1) -> 0 | C32: =COUNTIFS(KOL_Roster!$A$2:$A$76,$A32,KOL_Roster!$J$2:$J$76,2) -> 4 | D32: =COUNTIFS(KOL_Roster!$A$2:$A$76,$A32,KOL_Roster!$J$2:$J$76,3) -> 10 | E32: =SUM(B32:D32) -> 14 | G32: 14 named — one BELOW the 15 minimum (disclosed). Includes non-physician research KOLs (Birmingham Cerebra Centre).
A33: TOTAL | B33: =SUBTOTAL(9,B28:B32) -> 0 | C33: =SUBTOTAL(9,C28:C32) -> 13 | D33: =SUBTOTAL(9,D28:D32) -> 62 | E33: =SUBTOTAL(9,E28:E32) -> 75 | G33: No KOL reaches Tier 1 on evidence-floor scoring (see README) — engagement priority is tracked separately in KOL_Roster column I.
A35: D. KOL CROSS-CUTS (formulas on KOL_Roster)
A36: Cross-cut | B36: Count | G36: Definition
A37: KOLs with national/international guideline authorship | B37: =COUNTIF(KOL_Roster!$E$2:$E$76,"Yes*") -> 1 | G37: [P1] begins 'Yes' (Héron — PNDS).
A38: KOLs with a qualified (self-reported) guideline role | B38: =COUNTIF(KOL_Roster!$E$2:$E$76,"Qualified*") -> 1 | G38: Clayton-Smith — authorship unverified.
A39: KOLs with clinical-trial roles (ION582 or competitor) | B39: =COUNTIF(KOL_Roster!$G$2:$G$76,"*Trial*") -> 11 | G39: P2 field contains a trial entry.
A40: of which ION582 (HALOS / REVEAL) | B40: =COUNTIF(KOL_Roster!$G$2:$G$76,"*Trial (ION582)*") -> 8
A41: of which competitor trials | B41: =COUNTIF(KOL_Roster!$G$2:$G$76,"*Trial (competitor)*") -> 5
A42: KOLs with disease publications / datasets | B42: =COUNTIF(KOL_Roster!$G$2:$G$76,"*Disease:*") -> 51 | G42: P2 field contains a disease publication or study.
A43: KOLs with presentations at international meetings (verified) | B43: =COUNTIF(KOL_Roster!$H$2:$H$76,"Verified*") -> 0 | G43: 0 — conference evidence not retrieved for any KOL (see Verification_Flags #16).
A44: KOLs with a registry / natural-history coordinator role | B44: =COUNTIF(KOL_Roster!$F$2:$F$76,"Coordinator*") -> 12 | G44: [P3] begins 'Coordinator'.

Sheet Infrastructure
A1: Domain | B1: Capability | C1: Minimum requirement | D1: Typical Tier 1–2 coverage | E1: Notes / failure modes
A2: Diagnostics | B2: Molecular confirmation of AS genotype | C2: Methylation analysis (e.g. MS-MLPA) plus chromosomal microarray; UBE3A sequencing if still negative. REVEAL requires molecular confirmation of UBE3A deletion or mutation. | D2: Available through clinical-genetics services at Tier 1–2 (Manchester, Leipzig Human Genetics, Pitié-Salpêtrière, SJD offers Prader-Willi/Angelman methylation studies, Auxologico molecular lab). | E2: Roughly 80% of AS is identified by these tests; ~20% remain without genetic diagnosis (NHS GeNotes). UPD and imprinting-centre defects are EXCLUDED from REVEAL/HALOS — a CHAMPION Phase 3 (UPD/ID) is planned — so genotype gating drives addressable patients.
A3: Diagnostics | B3: EEG phenotyping and EEG biomarkers | C3: Standard + sleep EEG; AS-typical high-amplitude slow/spike patterns; EEG δ-power used as a pharmacodynamic biomarker in HALOS and rugonersen TANGELO. | D3: Tier 1–2 epilepsy/neurophysiology units (Munich EEG; Medea high-density EEG research; EpiCARE members). | E3: Practice variation in EEG protocols across sites; standardisation needed for any EEG-based secondary analysis.
A4: Severity assessment | B4: Developmental / functional outcome assessment | C4: Clinician-administered Bayley-4 (REVEAL primary endpoint: expressive communication), Vineland-3, SAS-CGI-C, sleep and caregiver-reported measures. | D4: Tier 1 trial sites with trained raters (HALOS/REVEAL sites; Aspire sites used Bayley-4 cognition). | E4: Rater availability and language standardisation across DE/FR/IT/ES/UK; age-band coverage (REVEAL ≥2 y; HALOS expanded <2 y).
A5: Severity assessment | B5: Seizure and sleep burden tracking | C5: Seizure and sleep diaries; actigraphy where available (FAST UK NatHis uses ActiMyo, EEG, diaries). | D5: Oxford NatHis cohort; Birmingham Cerebra sleep research; Manchester MDT. | E5: Epilepsy in ~80–90% of AS; status epilepticus in last 6 months is a HALOS exclusion.
A6: Treatment | B6: Symptomatic multidisciplinary standard of care | C6: ASF consensus framework (genetics, developmental medicine, psychology, neurology incl. movement, sleep, psychiatry, orthopaedics, ophthalmology, communication/AAC, early intervention, caregiver health). Antiseizure and sleep management; ketogenic / low-GI diet (Munich). | D6: ASF clinics (Munich, Leipzig, Aachen, Parc Taulí), Manchester AS Clinic, Stella Maris. | E6: Disparities in management even at expert clinics are a stated driver of the consensus; Munich offers a 3-day compact programme for distant families.
A7: Treatment | B7: DIFFERENTIATING INFRASTRUCTURE — paediatric lumbar puncture / intrathecal administration under sedation or anaesthesia | C7: REVEAL requires participants who can undergo sedation and/or general anaesthesia WITHOUT intubation; ION582 is given as a lumbar intrathecal bolus (80 mg) every 12 weeks in the double-blind period (EU control arm: skin-prick sham). Key exclusions: spine/bone/bleeding disorders or brain/spinal disease that interfere with lumbar puncture. | D7: Trial sites with paediatric anaesthesia + LP capability (LMU, Parc Taulí, Stella Maris, Oxford, GOSH, Necker). Aspire sites already ran sham-LP procedures. | E7: This is the single most differentiating piece of infrastructure: not every neuropaediatric centre has routine paediatric intrathecal dosing under sedation. Scoliosis/hip complications in AS can complicate LP. Many Tier 3 EpiCARE centres lack AS-specific dosing experience.
A8: Treatment | B8: Reimbursement / access pathway | C8: Country-specific specialist-care funding: Germany SPZ (children) and MZEB (adults; Aachen); France national PNDS / CRMR / DéfiScience network; Spain CSUR reference units (SJD, Virgen del Rocío) and regional XUEC; Italy national referral-centre network; UK NHS referrals — out-of-region referrals to Manchester may need funding agreement. | D8: Tier 1–2 centres sit within these pathways. | E8: No approved disease-modifying AS therapy; any future access will hinge on country HTA — not assessed here.
A9: Rehabilitation / chronic management | B9: Physio / OT / speech-language therapy and AAC; orthopaedics | C9: Lifelong multidisciplinary rehabilitation; AAC for ~85% non-speaking; scoliosis/hip surveillance. | D9: Munich (team of PT/OT/SLT, orthopaedics, AAC); Manchester MDT (SLT, physio, psychology); Leipzig SPZ. | E9: Local community therapy provision outside clinics is variable (France CAMSP/SESSAD; Germany Frühförderung/SPZ).
A10: Rehabilitation / chronic management | B10: Transition to adult care | C10: Defined paediatric-to-adult pathway; adult clinicians familiar with AS (REVEAL Cohort 2 includes 18–≤50 y). | D10: Aachen AZA (adults, Germany), Parc Taulí (paediatric + adult), Manchester (all ages). | E10: Adult capacity is thin in FR/IT/UK outside Manchester; Munich explicitly refers adults onward.
A11: Future-state | B11: ION582 administration capability and asset overlay | C11: Quarterly (Q12W) 80 mg lumbar intrathecal bolus after sedation; 60-week double-blind period then ~25-month long-term extension; Phase 3 topline 2H 2027. | D11: REVEAL/HALOS sites; ASO-experienced competitor-trial sites (Aspire, TANGELO). | E11: ASSET OVERLAY: ION582's quarterly intrathecal bolus is lighter than a loading-dose regimen (GTX-102 Aspire used monthly loading doses) but still needs sedation + LP capability. The addressable centre base is therefore the set of neuropaediatric centres with paediatric anaesthesia and LP capacity — wider than the ~10 AS-specialist clinics, narrower than all tertiary hospitals. Ionis states EU controls undergo a sham skin-prick, which sites must be able to run.
A12: Future-state | B12: RWE / registry participation capability | C12: Ability to enter longitudinal data: natural-history cohorts, national registers, ASF-style clinic data. | D12: Oxford NatHis (40 pts), Puerta de Hierro/Parc Taulí FAST Spain NH (≈40 pts), Leipzig German AS register, RISA (82 pts, closed), IReAS (213 pts, 14 Italian centres), Manchester register. | E12: Registries are national and not harmonised; RISA enrolment closed. A pan-EU4+UK RWE layer would need a common data model.
A13: Future-state | B13: Genotype expansion and post-trial access | C13: Capacity to serve UPD/ID patients (CHAMPION) and children <2 y; LTE continuity. | D13: Centres already running HALOS (including <2 y) and LTE. | E13: Plan referral flows for non-deletion/non-mutation genotypes now excluded from REVEAL.

Sheet Sources_Caveats
A1: Authoritative source | B1: URL / reference | C1: What it provides
A2: P1 — Duis et al. 2022, consensus statement on standards of care for Angelman syndrome. Mol Genet Genomic Med 10(3):e1843 | B2: https://doi.org/10.1002/mgg3.1843 | C2: International AS standards-of-care consensus; author and affiliation list (no EU4+UK author identified in retrieved portion).
A3: P1 (national) — HAS portal: PNDS Syndrome d'Angelman (Nov 2021) | B3: https://www.has-sante.fr/jcms/p_3300847/fr/syndrome-d-angelman | C3: French national diagnosis and care protocol; prepared by the CRMR Déficiences intellectuelles de causes rares (not HAS-validated).
A4: PNDS Angelman — argumentaire (coordinator Dr Delphine Héron) | B4: https://www.has-sante.fr/upload/docs/application/pdf/2021-11/argumentaire_pnds_angelman_vf.pdf | C4: Names coordinating centre (APHP Sorbonne Université) and coordinator.
A5: ION582 REVEAL — ClinicalTrials.gov NCT06914609 | B5: https://clinicaltrials.gov/study/NCT06914609 | C5: Pivotal Phase 3 record (design, endpoints, locations; dynamic page).
A6: ION582 REVEAL — EU CTIS 2024-519711-33-01 | B6: https://ctis.eu/trial/2024-519711-33-01 | C6: EU status 'Ongoing, recruiting'; 4 EU/EEA countries, 8 sites; start 17 Apr 2026.
A7: REVEAL — trial mirror (status 'Active, not recruiting'; 41 locations; 156 enrolled) | B7: https://ctv.veeva.com/study/reveal-a-phase-3-study-of-ion582-in-angelman-syndrome | C7: Design (80 mg vs placebo; cohorts) and amendment Dec 2025; status conflicts with CTIS — see Verification_Flags.
A8: Ionis community letter — first EU REVEAL sites (Apr 2026) | B8: https://angelman.org/wp-content/uploads/2026/04/Ionis-REVEAL-sites-EU_community-letter.pdf | C8: LMU München and Parc Taulí Sabadell activated; DE/IT/PL/ES expansion; EU sham skin-prick control.
A9: Ionis community update (Dec 2025) | B9: https://angelman.org/wp-content/uploads/2025/12/Community-Update-ION582-Ionis_Dec-2025.pdf | C9: Dose focus to 80 mg; REVEAL enrolment reduced to ~158; CHAMPION (UPD/ID) planned; HALOS <2 y.
A10: Ionis community update (Jul 2026) | B10: https://angelman.org/wp-content/uploads/2026/07/Ionis-update-REVEAL-July2026.pdf | C10: Cohort 1 enrolment complete; Cohort 2 still screening; results 2H 2027.
A11: Ionis IR — Cohort 1 complete (6 Jul 2026) | B11: https://ir.ionis.com/news-releases/news-release-details/ionis-completes-enrollment-pivotal-cohort-phase-3-reveal-study | C11: 136 pivotal participants; topline 2H 2027.
A12: Ionis IR — FDA Breakthrough Therapy designation (9 Sep 2025) | B12: https://ir.ionis.com/news-releases/news-release-details/ionis-receives-us-fda-breakthrough-therapy-designation-ion582 | C12: Regulatory premise; Orphan (FDA/EMA), Fast Track, Rare Pediatric.
... A69: Clinical — NHS GeNotes: Angelman syndrome | B69: https://www.genomicseducation.hee.nhs.uk/genotes/knowledge-hub/angelman-syndrome/ | C69: Diagnostic testing pathway; ~20% without genetic diagnosis.
A71: CAVEATS
A72: Coverage limits | B72: ClinicalTrials.gov/CTIS site tables are dynamic; REVEAL has 41 global locations but only LMU and Parc Taulí (EU) plus Oxford/GOSH (UK) were confirmable, and four Italian centres via Italian communications. Individual PI names for most sites are not public (HALOS: Battini, Bahi-Buisson, UK Oxford site via NatHis leads; REVEAL: D'Arrigo, Danieli, Pietrafusa).
A73: Per-geography gaps | B73: UK post-Brexit (P4 N/A). France: no REVEAL site named. Germany: ERN membership of AS clinics unconfirmed. Italy: IReAS centre list not public; Tier 3 from a patient-association list. Spain: other REVEAL sites beyond Parc Taulí not confirmed.
A74: KOL-movement warnings | B74: KOLs move: Makowski (Schwabing/kbo → LMU), Arzimanoglou (Lyon → Barcelona), Clayton-Smith (ERN coordinator role ended 2018). Verify affiliations before outreach.
A75: Gap-fill disclosure | B75: Gap-fill order (a)→(c) used as described in README; (d) hospital directories only for named centres. Untraceable cells read 'Not publicly identified — verify locally'.
A76: Tier-4 omission rationale | B76: Tier 4 was not requested; AS is chronic and managed at specialist clinics, so community hospitals matter mainly for case-finding and pharmacovigilance — handled via patient-association and national-society channels.
A77: Trial-readiness validation checklist | B77: For each shortlisted site confirm: (1) paediatric LP/IT dosing under sedation without intubation; (2) trained Bayley-4/Vineland raters; (3) EEG capability; (4) adult pathway (Cohort 2); (5) current REVEAL/Aspire/BEACON commitments and screen-failure load; (6) ethics/CTIS authorisation for ION582 in that country; (7) genotype pipeline (deletion/mutation vs UPD/ID).
A78: Asset-specific signal — endorsers / evidence partners | B78: Evidence partners surfaced: HALOS investigators Battini (Pisa), Bahi-Buisson (Necker), Oxford/Servais-Kini; REVEAL site investigators D'Arrigo (Besta), Danieli (Medea), Pietrafusa (Bambino Gesù); LMU (Makowski) and Parc Taulí (Roche) as first EU sites. No named public endorsements of ION582 by EU4+UK clinicians were retrieved.
A79: Competitive context | B79: GTX-102 (Aspire) — reported failure of both endpoints (secondary source). Rugonersen — Phase 3 BEACON ongoing. Alogabat — a Roche update (30 Mar 2026) exists; content not retrieved. Competitor-trial investigators carry confidentiality / conflict considerations (COMPLIANCE-relevant).
A80: Scoring caveat | B80: KOL scores are evidence-floor scores from web sources (see README). No PubMed counts, CVs or congress programmes were pulled; conference column is 'Not verified' for all KOLs.
A81: URL verification | B81: URLs were taken from search results; automated HTTP checks from the build sandbox returned 403 (bot-blocking) for all tested hosts, so link resolution could not be machine-verified. Click-test before circulation.
A82: Regional-extension scope note | B82: No regional extension (MENA, LATAM, APAC, EU-rest) was added: scope is EU4+UK only. EU-specific columns therefore read Yes/No for DE/FR/IT/ES and N/A (post-Brexit) for UK.

Sheet Verification_Flags
A1: # | B1: Sheet | C1: Cell(s) | D1: Item | E1: Finding | F1: Recommended correction | G1: Verdict
A2: 1 | B2: KOL_Roster | C2: D63 | D2: Clayton-Smith — ERN-ITHACA role | E2: AngelmanUK experts page presents her as ERN-ITHACA coordinator; ERN-ITHACA states coordination moved to AP-HP (Verloes) in Nov 2018 and the UK left the ERN framework post-Brexit. | F2: Describe as founding coordinator (2017–18); do not present as current. Retain Tier 1 on clinic/register role. | G2: OUTDATED
A3: 2 | B3: KOL_Roster | C3: E63 | D3: Clayton-Smith — guideline authorship | E3: Self-reported involvement in AS consensus criteria / management guidelines; she is not in the retrieved Duis 2022 affiliation list; no guideline citation retrieved. | F3: Verify authorship via PubMed before treating as P1. | G3: PART-UNVERIFIABLE
A4: 3 | B4: KOL_Roster | C4: C2 | D4: Makowski — affiliation currency | E4: 2021 AZM flyer lists München Klinik Schwabing / kbo; current LMU and ASF pages list LMU iSPZ Hauner (Neuropediatrics 2025 also LMU). Both appear in different sources. | F4: Use LMU iSPZ Hauner; confirm any residual kbo role. | G4: OUTDATED
A5: 4 | B5: KOL_Roster | C5: C8, C7 | D5: Burdach and Mall — only source is a 2021 flyer | E5: Roles (Chefarzt Schwabing; kbo medical director/TUM chair) come solely from the 2021 AZM flyer; AZM has since moved to LMU. | F5: Verify current positions or drop before outreach. | G5: PART-UNVERIFIABLE
A6: 5 | B6: KOL_Roster | C6: C62 | D6: Arzimanoglou — location | E6: Older French directories place him at HCL Lyon (to 2023); EpiCARE pages list him as Director of the Epilepsy Program at SJD Barcelona. | F6: Keep under Spain; epilepsy-network (AS-adjacent) KOL only. | G6: OUTDATED
A7: 6 | B7: KOL_Roster | C7: C41, C42, C43, C44, C45 | D7: IReAS co-authors — affiliation not stated | E7: Names come from the IReAS (EJMG 2026) author list; the retrieved record shows no affiliations or titles. | F7: Look up affiliations in the full paper before use; titles were deliberately omitted. | G7: PART-UNVERIFIABLE
A8: 7 | B8: KOL_Roster | C8: C73, C74, C76 | D8: UK affiliations inferred or unstated | E8: Gringras (affiliation not in retrieved record); Cross (GOSH inferred from EpiCARE 2017 lead-centre appointment); Moss (Google Scholar listing only). | F8: Verify affiliations; Cross and Gringras are AS-adjacent. | G8: PART-UNVERIFIABLE
A9: 8 | B9: Country_Centres | C9: I42 | D9: GOSH — REVEAL activation | E9: Evidence is a FAST UK LinkedIn post; no registry record or PI name retrieved. | F9: Confirm on ClinicalTrials.gov / HRA and identify PI. | G9: PART-UNVERIFIABLE
A10: 9 | B10: Country_Centres | C10: J18, J20, J21, J19 | D10: Italian REVEAL sites — activation status | E10: Italian communications (21 May 2026) name four 'involved' centres; the April 2026 Ionis letter had only LMU and Parc Taulí activated and Italy 'in progress'. CTIS lists 8 EU sites in 4 countries without names retrieved. | F10: Verify activation per centre in CTIS / ClinicalTrials.gov. | G10: PART-UNVERIFIABLE
A11: 10 | B11: Country_Centres | C11: K2, K3, K4, K33, K34, K18, K21, K23 | D11: P4 — ERN / national-reference membership unconfirmed | E11: These AS clinics were not found on the retrieved ERN-EpiCARE list or the (truncated) Orphanet ERN-ITHACA list; national-equivalent designations are asserted from clinic/IRCCS status only. | F11: Check the EC ERN Service Directory and national designations; Tier 1 'national equivalent' logic depends on this. | G11: PART-UNVERIFIABLE
A12: 11 | B12: Country_Centres | C12: I10 | D12: Necker — HALOS wording | E12: HALOS is closed to inclusions (AP-HP registry; 'active, not recruiting'); Necker's ION582 role is historical and not a REVEAL site. | F12: Describe as HALOS (completed enrolment) site; do not imply active ION582 recruitment. | G12: WORDING
A13: 12 | B13: README | C13: B7 | D13: Drug premise — REVEAL registry status | E13: CTIS: 'Ongoing, recruiting', 4 EU countries / 8 sites; mirror: 'Active, not recruiting', 156 enrolled, 41 locations; Ionis: Cohort 1 complete (136), ~158 target, Cohort 2 still screening. Primary-endpoint result not yet reported (topline 2H 2027). | F13: Treat REVEAL as 'recruiting adult cohort / pivotal cohort enrolled'; re-check registry before citing. | G13: WORDING
... A21: 20 | B21: Sources_Caveats | C21: A81, B81 | D21: URL resolution | E21: Links were copied from search results; automated checks from the sandbox returned HTTP 403 for all tested hosts, so resolution is not machine-verified. | F21: Click-test the source table before circulation. | G21: PART-UNVERIFIABLE
A23: Passed | B23: Checked and passed: asset facts (REVEAL NCT06914609 / EU CT 2024-519711-33-01; FDA BTD 9 Sep 2025; REVEAL amended Dec 2025 to 80 mg vs control; Cohort 1 136 participants, topline 2H 2027; HALOS NCT05127226, 71 participants); first EU REVEAL sites LMU + Parc Taulí; HALOS sites Necker / Pisa / Oxford; Aspire site list (DE: UKE, Leipzig, Munich; ES: SJD, Parc Taulí, Puerta de Hierro, Virgen del Rocío); France PNDS authorship (Héron, APHP Sorbonne Université); ASF clinics (Munich, Leipzig, Aachen, Parc Taulí) and named leads; natural-history studies (Oxford NCT05100810; FAST Spain NCT06115109) and their leads; A-MANECE and TANGELO author lists; IReAS/RISA papers. No KOL was found to be a pharma employee. These 20 flags are the only items requiring your decision; nothing was auto-corrected.
